Workbook
Name \0: #REF!
Name \0: #REF!
Name \a: #REF!
Name \a: #REF!
Name \d: #REF!
Name \d: #REF!
Name \e: #REF!
Name \e: #REF!
Name \f: #REF!
Name \f: #REF!
Name \g: #REF!
Name \g: #REF!
Name \h: #REF!
Name \h: #REF!
Name \i: #REF!
Name \i: #REF!
Name \j: #REF!
Name \j: #REF!
Name \k: #REF!
Name \k: #REF!
Name \l: #REF!
Name \l: #REF!
Name \m: #REF!
Name \m: #REF!
Name \n: #REF!
Name \n: #REF!
Name \o: #REF!
Name \o: #REF!
Name \p: #REF!
Name \p: #REF!
Name \T: #REF!
Name \T: #REF!
Name \z: #REF!
Name \z: #REF!
Name _: #REF!
Name _: #REF!
Name _?: #REF!
Name _?: #REF!
Name _??: #REF!
Name _??: #REF!
Name _???: #REF!
Name _???: #REF!
Name _??????: #REF!
Name _??????: #REF!
Name __________FIL2: #REF!
Name __________FIL2: #REF!
Name __________Ph30: #REF!
Name __________Ph30: #REF!
Name __________PXB80: #REF!
Name __________PXB80: #REF!
Name __________xb80: #REF!
Name __________xb80: #REF!
Name _____A65700: #REF!
Name _____A65700: #REF!
Name _____A65800: #REF!
Name _____A65800: #REF!
Name _____A67000: #REF!
Name _____A67000: #REF!
Name _____A68000: #REF!
Name _____A68000: #REF!

Sheet 1. Tổng hợp
A1: BẢNG TỔNG HỢP
A3: I | B3: Hiệu quả tài chính của dự án | C3: Đơn vị | D3: Giá trị
A4: 1 | B4: Dòng tiền dự án
B5: IRR dự án | C5: % | D5: ='8. Hiệu quả dự án và CĐT'!C21 -> 0.11584594
B6: NPV dự án | C6: đồng | D6: ='8. Hiệu quả dự án và CĐT'!C20 -> 7.6848969e+10
B7: IRR chủ đầu tư | C7: % | D7: ='8. Hiệu quả dự án và CĐT'!C49 -> 0.17607408
B8: NPV chủ đầu tư | C8: đồng | D8: ='8. Hiệu quả dự án và CĐT'!C48 -> 1.6125998e+10
B9: Return on Investment (ROI) | C9: % | D9: ='7. P&L TOÀN DỰ ÁN'!C24/('3. TMDT'!G15-'4. Vay'!C9) -> 0.45114229
A10: 2 | B10: Dòng tiền ngân hàng
B11: Vay ngân hàng | C11: đồng | D11: ='4. Vay'!C9 -> 7.9947434e+11
B12: Thời gian vay vốn | C12: năm | D12: =(COUNTIF('4. Vay'!E11:AS11,">1")+1)/4 -> 4
B13: Thời gian ân hạn | C13: năm | D13: =COUNTBLANK('4. Vay'!N10:AG10)/4 -> 2
A15: II | B15: Phương án Kinh doanh | C15: Đơn vị | D15: Giá trước thuế | E15: Thuế GTGT | F15: Giá sau thuế
B16: Tỷ lệ tăng giá bán hàng năm | C16: 0
A18: III | B18: Các chi phí khác
A19: 1 | B19: Chi phí bán hàng | C19: % doanh thu | D19: =D20+D21 -> 0.02
B20: Chi phí hoa hồng đại lý, môi giới | C20: % doanh thu | D20: 0
B21: Truyền thông Marketing | C21: % doanh thu | D21: 0.02
A22: 2 | B22: Chính sách bán hàng | C22: % doanh thu | D22: 0
A23: 3 | B23: Chi phí quản lý doanh nghiệp | C23: % doanh thu | D23: 0.02
A24: 4 | B24: Thuế VAT | D24: 0.1
A25: 5 | B25: Thuế TNDN | D25: 0.2
A26: 6 | B26: Lãi vay ngân hàng | C26: %/năm | D26: ='4. Vay'!E7*2/5+'4. Vay'!U7*3/5 -> 0.065
A29: IV | B29: Cơ cấu vốn | C29: Giá trị | D29: Tỷ lệ | E29: Chi phí vốn
A30: 1 | B30: Vốn CSH | C30: ='9. Cân đối dòng tiền (VCSH)'!C9 -> 249000000000 | D30: =C30/$C$33 -> 0.2097507 | E30: 0.15
A31: 3 | B31: Vốn vay | C31: ='9. Cân đối dòng tiền (VCSH)'!C8 -> 7.9947434e+11 | D31: =C31/$C$33 -> 0.67345503 | E31: =D26 -> 0.065
A32: 4 | B32: Vốn huy động khác (doanh thu bán hàng) | C32: =C33-C31-C30 -> 1.3864923e+11 | D32: =C32/$C$33 -> 0.11679427 | E32: 0.05
B33: TMĐT | C33: ='3. TMDT'!G15 -> 1.1871236e+12 | D33: =SUM(D30:D32) -> 1 | E33: =D30*E30+D31*E31*(1-D25)+D32*E32 -> 0.07232198
F35: IRR dự án
G36: Tỷ lệ thay đổi TMĐT
B37: Tỷ lệ thay đổi giá bán | C37: =0% -> 0 | E37: Tỷ lệ thay đổi giá bán | F37: =D5 -> 0.11584594 | G37: -0.05 | H37: -0.04 | I37: -0.03 | J37: -0.02 | K37: -0.01 | L37: 0 | M37: 0.01 | N37: 0.02 | O37: 0.03 | P37: 0.04 | Q37: 0.05
B38: Tỷ lệ thay đổi TMĐT | C38: =0% -> 0 | F38: -0.2 | G38: 0.14242528 | H38: 0.13686422 | I38: 0.13142963 | J38: 0.12611755 | K38: 0.12092421 | L38: 0.11584594 | M38: 0.11087925 | N38: 0.10602076 | O38: 0.10126724 | P38: 0.096615566 | Q38: 0.092062741
F39: -0.15 | G39: 0.14242528 | H39: 0.13686422 | I39: 0.13142963 | J39: 0.12611755 | K39: 0.12092421 | L39: 0.11584594 | M39: 0.11087925 | N39: 0.10602076 | O39: 0.10126724 | P39: 0.096615566 | Q39: 0.092062741
F40: -0.1 | G40: 0.14242528 | H40: 0.13686422 | I40: 0.13142963 | J40: 0.12611755 | K40: 0.12092421 | L40: 0.11584594 | M40: 0.11087925 | N40: 0.10602076 | O40: 0.10126724 | P40: 0.096615566 | Q40: 0.092062741
F41: -0.05 | G41: 0.14242528 | H41: 0.13686422 | I41: 0.13142963 | J41: 0.12611755 | K41: 0.12092421 | L41: 0.11584594 | M41: 0.11087925 | N41: 0.10602076 | O41: 0.10126724 | P41: 0.096615566 | Q41: 0.092062741
F42: 0 | G42: 0.14242528 | H42: 0.13686422 | I42: 0.13142963 | J42: 0.12611755 | K42: 0.12092421 | L42: 0.11584594 | M42: 0.11087925 | N42: 0.10602076 | O42: 0.10126724 | P42: 0.096615566 | Q42: 0.092062741
F43: 0.05 | G43: 0.14242528 | H43: 0.13686422 | I43: 0.13142963 | J43: 0.12611755 | K43: 0.12092421 | L43: 0.11584594 | M43: 0.11087925 | N43: 0.10602076 | O43: 0.10126724 | P43: 0.096615566 | Q43: 0.092062741
F44: 0.1 | G44: 0.14242528 | H44: 0.13686422 | I44: 0.13142963 | J44: 0.12611755 | K44: 0.12092421 | L44: 0.11584594 | M44: 0.11087925 | N44: 0.10602076 | O44: 0.10126724 | P44: 0.096615566 | Q44: 0.092062741
F45: 0.15 | G45: 0.14242528 | H45: 0.13686422 | I45: 0.13142963 | J45: 0.12611755 | K45: 0.12092421 | L45: 0.11584594 | M45: 0.11087925 | N45: 0.10602076 | O45: 0.10126724 | P45: 0.096615566 | Q45: 0.092062741
F46: 0.2 | G46: 0.14242528 | H46: 0.13686422 | I46: 0.13142963 | J46: 0.12611755 | K46: 0.12092421 | L46: 0.11584594 | M46: 0.11087925 | N46: 0.10602076 | O46: 0.10126724 | P46: 0.096615566 | Q46: 0.092062741
...

Sheet 2. CPxaydung
A1: BẢNG 2: TỔNG HỢP CÁC CHI PHÍ XÂY DỰNG
H4: Đơn vị: vnđ
A5: STT | B5: Khoản mục chi phí | C5: Ký hiệu | D5: Diễn giải tính toán | G5: Thành tiền trước thuế | H5: Thuế GTGT | I5: Thành tiền sau thuế | J5: Ghi chú | L5: Tổng | M5: 45291 | N5: =EOMONTH(M5,3) -> 45382 | O5: =EOMONTH(N5,3) -> 45473 | P5: =EOMONTH(O5,3) -> 45565 | Q5: =EOMONTH(P5,3) -> 45657 | R5: =EOMONTH(Q5,3) -> 45747 | S5: =EOMONTH(R5,3) -> 45838 | T5: =EOMONTH(S5,3) -> 45930 | U5: =EOMONTH(T5,3) -> 46022 | ... BA5: =EOMONTH(AZ5,3) -> 48944
A6: A | B6: Chi phí xây dựng, thiết bị | C6: Gxd | G6: =SUM(G7:G9) -> 8.6824028e+11 | H6: =SUM(H7:H9) -> 8.6824028e+10 | I6: =SUM(I7:I9) -> 955064310000 | K6: =I6-L6 -> 0 | L6: =SUM(L7:L9) -> 955064310000 | M6: =SUM(M7:M9) -> 0 | N6: =SUM(N7:N9) -> 0 | O6: =SUM(O7:O9) -> 0 | P6: =SUM(P7:P9) -> 0 | Q6: =SUM(Q7:Q9) -> 0 | R6: =SUM(R7:R9) -> 0 | S6: =SUM(S7:S9) -> 0 | ... BA6: =SUM(BA7:BA9) -> 0
A7: 1 | B7: Chi phí xây dựng và thiết bị phần hạ tầng kỹ thuật | G7: =I7/(1+'1. Tổng hợp'!$D$24) -> 2.8275455e+10 | H7: =+G7*0.1 -> 2.8275455e+09 | I7: =31103000000*(1+'1. Tổng hợp'!$C$38) -> 31103000000 | K7: =I7-L7 -> 0 | L7: =SUM(M7:BA7) -> 31103000000 | M7: 0 | V7: =I7/8 -> 3887875000 | W7: =V7 -> 3887875000 | X7: =W7 -> 3887875000 | Y7: =X7 -> 3887875000 | Z7: =Y7 -> 3887875000 | AA7: =Z7 -> 3887875000 | AB7: =AA7 -> 3887875000 | AC7: =AB7 -> 3887875000
A8: 2 | B8: Chi phí xây dựng và thiết bị phần nhà ở, thương mại dịch vụ, công trình công cộng và y tế, giáo dục | G8: =I8/(1+'1. Tổng hợp'!$D$24) -> 7.8697364e+11 | H8: =+G8*0.1 -> 7.8697364e+10 | I8: =865671000000*(1+'1. Tổng hợp'!$C$38) -> 865671000000 | K8: =I8-L8 -> 0 | L8: =SUM(M8:AC8) -> 865671000000 | V8: =I8/8 -> 108208875000 | W8: =V8 -> 108208875000 | X8: =W8 -> 108208875000 | Y8: =X8 -> 108208875000 | Z8: =Y8 -> 108208875000 | AA8: =Z8 -> 108208875000 | AB8: =AA8 -> 108208875000 | AC8: =AB8 -> 108208875000
A9: 3 | B9: Chi phí quản lý dự án, chi phí tư vấn và chi phí khác | G9: =I9/(1+'1. Tổng hợp'!$D$24) -> 5.2991191e+10 | H9: =+G9*0.1 -> 5.2991191e+09 | I9: =58290310000*(1+'1. Tổng hợp'!$C$38) -> 58290310000 | K9: =I9-L9 -> 0 | L9: =SUM(M9:AC9) -> 58290310000 | V9: =I9/8 -> 7286288750 | W9: =V9 -> 7286288750 | X9: =W9 -> 7286288750 | Y9: =X9 -> 7286288750 | Z9: =Y9 -> 7286288750 | AA9: =Z9 -> 7286288750 | AB9: =AA9 -> 7286288750 | AC9: =AB9 -> 7286288750
A10: B | B10: Chi phí quản lý dự án + tư vấn + khác | C10: Gqlda | G10: =I10/(1+'1. Tổng hợp'!$D$24) -> 0 | H10: =+G10*0.1 -> 0 | I10: =0*(1+'1. Tổng hợp'!$C$38) -> 0 | K10: =I10-L10 -> 0 | L10: =SUM(M10:AC10) -> 0
A11: C | B11: Chi phí dự phòng | C11: Gdp | D11: 0.05 | E11: x(A+B+C+D+E) | G11: =I11/(1+'1. Tổng hợp'!$D$24) -> 1.3093411e+11 | H11: =+G11*0.1 -> 1.3093411e+10 | I11: =144027518205.24*(1+'1. Tổng hợp'!$C$38) -> 1.4402752e+11 | K11: =I11-L11 -> 0 | L11: =SUM(M11:AC11) -> 1.4402752e+11 | V11: =I11/8 -> 1.800344e+10 | W11: =V11 -> 1.800344e+10 | X11: =W11 -> 1.800344e+10 | Y11: =X11 -> 1.800344e+10 | Z11: =Y11 -> 1.800344e+10 | AA11: =Z11 -> 1.800344e+10 | AB11: =AA11 -> 1.800344e+10 | AC11: =AB11 -> 1.800344e+10
A12: D | B12: Tổng chi phí đầu tư | G12: =G6+G10+G11 -> 9.9917439e+11 | H12: =H6+H10+H11 -> 9.9917439e+10 | I12: =I6+I10+I11 -> 1.0990918e+12 | K12: =I12-L12 -> 0 | L12: =L6+L10+L11 -> 1.0990918e+12 | M12: =M6+M10+M11 -> 0 | N12: =N6+N10+N11 -> 0 | O12: =O6+O10+O11 -> 0 | P12: =P6+P10+P11 -> 0 | Q12: =Q6+Q10+Q11 -> 0 | R12: =R6+R10+R11 -> 0 | S12: =S6+S10+S11 -> 0 | ... BA12: =BA6+BA10+BA11 -> 0
A13: E | B13: LÀM TRÒN | D13: A+B+C+D+E+F | I13: =ROUND(I12,-3) -> 1099091828000

Sheet 3. TMDT
A1: BẢNG 3: TỔNG MỨC ĐẦU TƯ DỰ ÁN
G4: =SUM(G8:G8) -> 0 | H4: Đơn vị: vnđ
A5: STT | B5: Khoản mục chi phí | C5: Ký hiệu | D5: Cách tính | E5: Thành tiền trước thuế | F5: Thuế GTGT | G5: Thành tiền sau thuế | H5: Ghi chú | J5: Tổng | K5: ='2. CPxaydung'!M5 -> 45291 | L5: ='2. CPxaydung'!N5 -> 45382 | M5: ='2. CPxaydung'!O5 -> 45473 | N5: ='2. CPxaydung'!P5 -> 45565 | O5: ='2. CPxaydung'!Q5 -> 45657 | P5: ='2. CPxaydung'!R5 -> 45747 | Q5: ='2. CPxaydung'!S5 -> 45838 | R5: ='2. CPxaydung'!T5 -> 45930 | ... AY5: ='2. CPxaydung'!BA5 -> 48944
A6: A | B6: Tổng chi phí đầu tư xây dựng dự án | E6: =SUBTOTAL(9,E7:E9) -> 9.9917439e+11 | F6: =SUBTOTAL(9,F7:F9) -> 9.9917439e+10 | G6: =SUBTOTAL(9,G7:G9) -> 1.0990918e+12 | J6: =SUBTOTAL(9,J7:J9) -> 1.0990918e+12 | K6: =SUBTOTAL(9,K7:K9) -> 0 | L6: =SUBTOTAL(9,L7:L9) -> 0 | M6: =SUBTOTAL(9,M7:M9) -> 0 | N6: =SUBTOTAL(9,N7:N9) -> 0 | O6: =SUBTOTAL(9,O7:O9) -> 0 | P6: =SUBTOTAL(9,P7:P9) -> 0 | Q6: =SUBTOTAL(9,Q7:Q9) -> 0 | ... AY6: =SUBTOTAL(9,AY7:AY9) -> 0
A7: 1 | B7: ='2. CPxaydung'!B6 -> Chi phí xây dựng, thiết bị | C7: Gxd | E7: =SUMIFS('2. CPxaydung'!$G$5:$G$14,'2. CPxaydung'!$C$5:$C$14,'3. TMDT'!C7) -> 8.6824028e+11 | F7: =+E7*'1. Tổng hợp'!$D$24 -> 8.6824028e+10 | G7: =E7+F7 -> 9.5506431e+11 | I7: =G7-J7 -> 0 | J7: =SUM(K7:AY7) -> 955064310000 | K7: ='2. CPxaydung'!M6 -> 0 | L7: ='2. CPxaydung'!N6 -> 0 | M7: ='2. CPxaydung'!O6 -> 0 | N7: ='2. CPxaydung'!P6 -> 0 | O7: ='2. CPxaydung'!Q6 -> 0 | P7: ='2. CPxaydung'!R6 -> 0 | Q7: ='2. CPxaydung'!S6 -> 0 | R7: ='2. CPxaydung'!T6 -> 0 | ... AY7: ='2. CPxaydung'!BA6 -> 0
A8: 2 | B8: ='2. CPxaydung'!B10 -> Chi phí quản lý dự án + tư vấn + khác | C8: Gqlda | E8: =SUMIFS('2. CPxaydung'!$G$5:$G$14,'2. CPxaydung'!$C$5:$C$14,'3. TMDT'!C8) -> 0 | F8: =+E8*'1. Tổng hợp'!$D$24 -> 0 | G8: =E8+F8 -> 0 | I8: =G8-J8 -> 0 | J8: =SUM(K8:AY8) -> 0 | K8: ='2. CPxaydung'!M10 -> 0 | L8: ='2. CPxaydung'!N10 -> 0 | M8: ='2. CPxaydung'!O10 -> 0 | N8: ='2. CPxaydung'!P10 -> 0 | O8: ='2. CPxaydung'!Q10 -> 0 | P8: ='2. CPxaydung'!R10 -> 0 | Q8: ='2. CPxaydung'!S10 -> 0 | R8: ='2. CPxaydung'!T10 -> 0 | ... AE8: ='2. CPxaydung'!AG10 -> 0 | AF8: ='2. CPxaydung'!AD10 -> 0 | AG8: ='2. CPxaydung'!AE10 -> 0 | AH8: ='2. CPxaydung'!AF10 -> 0 | AI8: ='2. CPxaydung'!AG10 -> 0 | AJ8: ='2. CPxaydung'!AL10 -> 0 | AK8: ='2. CPxaydung'!AM10 -> 0 | AL8: ='2. CPxaydung'!AN10 -> 0 | AM8: ='2. CPxaydung'!AO10 -> 0 | AN8: ='2. CPxaydung'!AP10 -> 0 | AO8: ='2. CPxaydung'!AQ10 -> 0 | AP8: ='2. CPxaydung'!AR10 -> 0 | AQ8: ='2. CPxaydung'!AS10 -> 0 | ... AY8: ='2. CPxaydung'!BA10 -> 0
A9: 3 | B9: ='2. CPxaydung'!B11 -> Chi phí dự phòng | C9: Gdp | E9: =SUMIFS('2. CPxaydung'!$G$5:$G$14,'2. CPxaydung'!$C$5:$C$14,'3. TMDT'!C9) -> 1.3093411e+11 | F9: =+E9*'1. Tổng hợp'!$D$24 -> 1.3093411e+10 | G9: =E9+F9 -> 1.4402752e+11 | I9: =G9-J9 -> 0 | J9: =SUM(K9:AY9) -> 1.4402752e+11 | K9: ='2. CPxaydung'!M11 -> 0 | L9: ='2. CPxaydung'!N11 -> 0 | M9: ='2. CPxaydung'!O11 -> 0 | N9: ='2. CPxaydung'!P11 -> 0 | O9: ='2. CPxaydung'!Q11 -> 0 | P9: ='2. CPxaydung'!R11 -> 0 | Q9: ='2. CPxaydung'!S11 -> 0 | R9: ='2. CPxaydung'!T11 -> 0 | ... AE9: ='2. CPxaydung'!AG11 -> 0 | AF9: ='2. CPxaydung'!AD11 -> 0 | AG9: ='2. CPxaydung'!AE11 -> 0 | AH9: ='2. CPxaydung'!AF11 -> 0 | AI9: ='2. CPxaydung'!AG11 -> 0 | AJ9: ='2. CPxaydung'!AL11 -> 0 | AK9: ='2. CPxaydung'!AM11 -> 0 | AL9: ='2. CPxaydung'!AN11 -> 0 | AM9: ='2. CPxaydung'!AO11 -> 0 | AN9: ='2. CPxaydung'!AP11 -> 0 | AO9: ='2. CPxaydung'!AQ11 -> 0 | AP9: ='2. CPxaydung'!AR11 -> 0 | AQ9: ='2. CPxaydung'!AS11 -> 0 | ... AY9: ='2. CPxaydung'!BA11 -> 0
A10: B | B10: Chi phí GPMB và tiền sử dụng đất | E10: =G10 -> 43014372094 | F10: 0 | G10: =43014372094*(1+'1. Tổng hợp'!$C$38) -> 43014372094 | I10: =G10-J10 -> 0 | J10: =SUM(K10:AY10) -> 43014372094 | T10: =G10 -> 43014372094
A11: C | B11: Chi phí M&A | E11: 0 | G11: 0 | J11: =SUM(K11:AY11) -> 0
A12: D | B12: Chi phí PTDA | C12: PTDA | E12: 0 | G12: =+E12 -> 0 | J12: =SUM(K12:AY12) -> 0
A13: H | B13: Tổng cộng (A+B+C+D) | E13: =E6+E10+E11+E12 -> 1.0421888e+12 | F13: =F6+F10+F11+F12 -> 9.9917439e+10 | G13: =G6+G10+G11+G12 -> 1.1421062e+12 | I13: =G13-J13 -> 0 | J13: =J6+J10+J11+J12 -> 1.1421062e+12 | K13: =K6+K10+K11+K12 -> 0 | L13: =L6+L10+L11+L12 -> 0 | M13: =M6+M10+M11+M12 -> 0 | N13: =N6+N10+N11+N12 -> 0 | O13: =O6+O10+O11+O12 -> 0 | P13: =P6+P10+P11+P12 -> 0 | Q13: =Q6+Q10+Q11+Q12 -> 0 | ... AY13: =AY6+AY10+AY11+AY12 -> 0
A14: I | B14: Lãi vay trong giai đoạn xây dựng | C14: Lv | E14: =J14 -> 4.501737e+10 | G14: =E14 -> 4.501737e+10 | I14: =G14-J14 -> 0 | J14: =SUM(K14:AY14) -> 4.501737e+10 | K14: =+'4. Vay'!E22 -> 0 | L14: =+'4. Vay'!F22 -> 0 | M14: =+'4. Vay'!G22 -> 0 | N14: =+'4. Vay'!H22 -> 0 | O14: =+'4. Vay'!I22 -> 0 | P14: =+'4. Vay'!J22 -> 0 | Q14: =+'4. Vay'!K22 -> 0 | R14: =+'4. Vay'!L22 -> 0 | ... AY14: =+'4. Vay'!AS22 -> 0
B15: TỔNG VỐN ĐẦU TƯ (H+I+G) | C15: TVĐT | E15: =E13+E14 -> 1.0872061e+12 | F15: =F13+F14 -> 9.9917439e+10 | G15: =G13+G14 -> 1.1871236e+12 | I15: =G15-J15 -> 0 | J15: =J13+J14 -> 1.1871236e+12 | K15: =K13+K14 -> 0 | L15: =L13+L14 -> 0 | M15: =M13+M14 -> 0 | N15: =N13+N14 -> 0 | O15: =O13+O14 -> 0 | P15: =P13+P14 -> 0 | Q15: =Q13+Q14 -> 0 | ... AY15: =AY13+AY14 -> 0
B16: LÀM TRÒN | G16: =ROUND(G15,-6) -> 1187124000000 | J16: =SUM(K16:T16) -> 0

Sheet 4. Vay
A1: BẢNG 4: KẾ HOẠCH VAY VỐN
I4: 1 | J4: =I4+1 -> 2 | K4: =J4+1 -> 3 | L4: =K4+1 -> 4 | M4: =L4+1 -> 5 | N4: =M4+1 -> 6 | O4: =N4+1 -> 7 | P4: =O4+1 -> 8 | Q4: =P4+1 -> 9 | ... AS4: =AR4+1 -> 37
A5: STT | B5: CÁC YẾU TỐ | C5: TỔNG CỘNG | D5: Đơn vị | E5: KỲ VAY VỐN
E6: =+'5. KHBH'!FK4 -> 45291 | F6: =+'5. KHBH'!FL4 -> 45382 | G6: =+'5. KHBH'!FM4 -> 45473 | H6: =+'5. KHBH'!FN4 -> 45565 | I6: =+'5. KHBH'!FO4 -> 45657 | J6: =+'5. KHBH'!FP4 -> 45747 | K6: =+'5. KHBH'!FQ4 -> 45838 | L6: =+'5. KHBH'!FR4 -> 45930 | ... AS6: =+'5. KHBH'!GY4 -> 48944
B7: Lãi suất | D7: %/năm | E7: 0.065 | F7: =E7 -> 0.065 | G7: =+F7 -> 0.065 | H7: =+G7 -> 0.065 | I7: =+H7 -> 0.065 | J7: =E7 -> 0.065 | K7: =+J7 -> 0.065 | L7: =+K7 -> 0.065 | M7: =+L7 -> 0.065 | N7: =+M7 -> 0.065 | O7: =+N7 -> 0.065 | P7: =+O7 -> 0.065 | Q7: =P7 -> 0.065 | R7: =Q7 -> 0.065 | S7: =+R7 -> 0.065 | T7: =+S7 -> 0.065 | U7: =T7 -> 0.065 | V7: =+U7 -> 0.065 | W7: =+V7 -> 0.065 | X7: =+W7 -> 0.065 | Y7: =+X7 -> 0.065 | Z7: =+Y7 -> 0.065 | AA7: =+Z7 -> 0.065 | AB7: =+AA7 -> 0.065 | AC7: =+I7 -> 0.065 | AD7: =+J7 -> 0.065 | AE7: =+K7 -> 0.065 | AF7: =+L7 -> 0.065 | AG7: =+M7 -> 0.065 | AH7: =+N7 -> 0.065 | AI7: =+O7 -> 0.065 | AJ7: =+P7 -> 0.065 | ... AS7: =+Y7 -> 0.065
B8: Dư nợ đầu kỳ | D8: vnđ | I8: =+H11 -> 0 | J8: =+I11 -> 0 | K8: =+J11 -> 0 | L8: =+K11 -> 0 | M8: =+L11 -> 0 | N8: =+M11 -> 0 | O8: =+N11 -> 1.262806e+11 | P8: =+O11 -> 2.2245113e+11 | ... AS8: =+AR11 -> 0
B9: Giải ngân trong kỳ | C9: =SUM(E9:AS9) -> 7.9947434e+11 | D9: vnđ | E9: 0 | F9: 0 | G9: 0 | H9: 0 | M9: =('3. TMDT'!S6+'3. TMDT'!S10)*60% -> 0 | N9: =('3. TMDT'!T6+'3. TMDT'!T10)*70% -> 1.262806e+11 | O9: =('3. TMDT'!U6+'3. TMDT'!U10)*70% -> 9.6170535e+10 | P9: =('3. TMDT'!V6+'3. TMDT'!V10)*70% -> 9.6170535e+10 | Q9: =('3. TMDT'!W6+'3. TMDT'!W10)*70% -> 9.6170535e+10 | R9: =('3. TMDT'!X6+'3. TMDT'!X10)*70% -> 9.6170535e+10 | S9: =('3. TMDT'!Y6+'3. TMDT'!Y10)*70% -> 9.6170535e+10 | T9: =('3. TMDT'!Z6+'3. TMDT'!Z10)*70% -> 9.6170535e+10 | U9: =('3. TMDT'!AA6+'3. TMDT'!AA10)*70% -> 9.6170535e+10
B10: Trả nợ trong kỳ | C10: =SUM(E10:AS10) -> 7.9947434e+11 | D10: vnđ | R10: =C9/12 -> 6.6622862e+10 | S10: =R10 -> 6.6622862e+10 | T10: =S10 -> 6.6622862e+10 | U10: =T10 -> 6.6622862e+10 | V10: =U10 -> 6.6622862e+10 | W10: =V10 -> 6.6622862e+10 | X10: =W10 -> 6.6622862e+10 | Y10: =X10 -> 6.6622862e+10 | Z10: =Y10 -> 6.6622862e+10 | ... AB10: =AA10 -> 6.6622862e+10 | AC10: 6.6622862e+10
B11: Dư nợ cuối kỳ | D11: vnđ | E11: =+E8+E9-E10 -> 0 | F11: =+F8+F9-F10 -> 0 | G11: =+G8+G9-G10 -> 0 | H11: =+H8+H9-H10 -> 0 | I11: =+I8+I9-I10 -> 0 | J11: =+J8+J9-J10 -> 0 | K11: =+K8+K9-K10 -> 0 | L11: =+L8+L9-L10 -> 0 | ... AS11: =+AS8+AS9-AS10 -> 0
B12: Lãi vay trong kỳ | C12: =SUM(E12:AS12) -> 7.9661258e+10 | D12: vnđ | E12: 0 | F12: =+(F8+F11)*F7/(2*4) -> 0 | G12: =+(G8+G11)*G7/(2*4) -> 0 | H12: =+(H8+H11)*H7/(2*4) -> 0 | I12: =+(I8+I11)*I7/(2*4) -> 0 | J12: =+(J8+J11)*J7/(2*4) -> 0 | K12: =+(K8+K11)*K7/(2*4) -> 0 | L12: =+(L8+L11)*L7/(2*4) -> 0 | M12: =+(M8+M11)*M7/(2*4) -> 0 | ... AS12: =+(AS8+AS11)*AS7/(2*4) -> 0
B13: Kế hoạch trả lãi trong kỳ | C13: =SUM(E13:AS13) -> 7.9661258e+10 | D13: vnđ | E13: =+E12 -> 0 | F13: =+F12 -> 0 | G13: =+G12 -> 0 | H13: =+H12 -> 0 | I13: =+I12 -> 0 | J13: =+J12 -> 0 | K13: =+K12 -> 0 | L13: =+L12 -> 0 | ... AS13: =+AS12 -> 0
A15: TỔNG CẢ GỐC VÀ LÃI | C15: =+C10+C13 -> 8.791356e+11 | J15: =J10+J12 -> 0 | K15: =K10+K12 -> 0 | L15: =L10+L12 -> 0 | M15: =M10+M12 -> 0 | N15: =N10+N12 -> 1.0260298e+09 | O15: =O10+O12 -> 2.8334453e+09 | P15: =P10+P12 -> 4.3962165e+09 | Q15: =Q10+Q12 -> 5.9589877e+09 | ... AS15: =AS10+AS12 -> 0
J17: =+#REF!*J7/(2*4) -> #REF!
C18: =INDEX(F6:AS6,1,MATCH(C20,F20:AS20,0)) -> 46752
B19: Lãi vay
B20: Lũy kế chi phí xây dựng, thiết bị | C20: ='2. CPxaydung'!I6 -> 955064310000 | F20: =SUM('2. CPxaydung'!$N$6:'2. CPxaydung'!N6) -> 0 | G20: =SUM('2. CPxaydung'!$N$6:'2. CPxaydung'!O6) -> 0 | H20: =SUM('2. CPxaydung'!$N$6:'2. CPxaydung'!P6) -> 0 | I20: =SUM('2. CPxaydung'!$N$6:'2. CPxaydung'!Q6) -> 0 | J20: =SUM('2. CPxaydung'!$N$6:'2. CPxaydung'!R6) -> 0 | K20: =SUM('2. CPxaydung'!$N$6:'2. CPxaydung'!S6) -> 0 | L20: =SUM('2. CPxaydung'!$N$6:'2. CPxaydung'!T6) -> 0 | M20: =SUM('2. CPxaydung'!$N$6:'2. CPxaydung'!U6) -> 0 | ... AS20: =SUM('2. CPxaydung'!$N$6:'2. CPxaydung'!BA6) -> 955064310000
B21: Thời điểm kết thúc XD | C21: 46752
B22: Lãi vay trong giai đoạn xây dựng | C22: =SUM(E22:AS22) -> 4.501737e+10 | F22: =IF(F6<=$C$21,F12,0) -> 0 | G22: =IF(G6<=$C$21,G12,0) -> 0 | H22: =IF(H6<=$C$21,H12,0) -> 0 | I22: =IF(I6<=$C$21,I12,0) -> 0 | J22: =IF(J6<=$C$21,J12,0) -> 0 | K22: =IF(K6<=$C$21,K12,0) -> 0 | L22: =IF(L6<=$C$21,L12,0) -> 0 | M22: =IF(M6<=$C$21,M12,0) -> 0 | ... AS22: =IF(AS6<=$C$21,AS12,0) -> 0
B23: Lãi vay trong kỳ | C23: =SUM(E23:AS23) -> 3.4643888e+10 | F23: =IF(F6>$C$21,F12,0) -> 0 | G23: =IF(G6>$C$21,G12,0) -> 0 | H23: =IF(H6>$C$21,H12,0) -> 0 | I23: =IF(I6>$C$21,I12,0) -> 0 | J23: =IF(J6>$C$21,J12,0) -> 0 | K23: =IF(K6>$C$21,K12,0) -> 0 | L23: =IF(L6>$C$21,L12,0) -> 0 | M23: =IF(M6>$C$21,M12,0) -> 0 | ... AS23: =IF(AS6>$C$21,AS12,0) -> 0

Sheet 5. KHBH
B1: BẢNG 5: KẾ HOẠCH BÁN HÀNG | P1: =SUBTOTAL(9,P8:P11) -> 1535939420000
P2: =SUBTOTAL(9,P8:P11) -> 1535939420000 | Z2: =SUBTOTAL(9,Z8:Z11) -> 0 | AA2: =SUBTOTAL(9,AA8:AA11) -> 1535939420000 | AB2: 44742 | AC2: 44834 | AD2: =AC2 -> 44834 | AE2: =AD2 -> 44834 | AF2: =EOMONTH(AC2,3) -> 44926 | AG2: =EOMONTH(AD2,3) -> 44926 | AH2: =EOMONTH(AE2,3) -> 44926 | AI2: =EOMONTH(AF2,3) -> 45016 | AJ2: =EOMONTH(AG2,3) -> 45016 | AK2: =EOMONTH(AH2,3) -> 45016 | AL2: =EOMONTH(AI2,3) -> 45107 | AM2: =EOMONTH(AJ2,3) -> 45107 | ... FJ2: =EOMONTH(FG2,3) -> 48944
B3: STT | C3: SẢN PHẨM | I3: LOẠI SẢN PHẦM | J3: THỜI GIAN BÁN | K3: KẾ HOẠCH BÁN HÀNG | R3: TIẾN ĐỘ THU TIỀN THÔNG THƯỜNG | AB3: KẾ HOẠCH THU TIỀN THEO THÁNG | FK3: KẾ HOẠCH THU TIỀN THEO QUÝ
B4: STT | D4: MÃ CĂN | E4: NOTE 1 | F4: NOTE 2 | G4: NOTE 3 | H4: KHU VỰC | K4: Số căn | L4: Diện tích xây dựng | M4: Diện tích thương phẩm | N4: DG đất + xây (gồm VAT) | O4: DG đất + xây có tăng giá (gồm VAT) | P4: Tổng giá trị hợp đồng | Q4: Thời điểm ghi nhận doanh thu | R4: Đợt 1 | S4: Đợt 2 | T4: Đợt 3 | U4: Đợt 4 | V4: Đợt 5 | W4: Đợt 6 | X4: Đợt 7 | Y4: Đợt 8 | AB4: 44713 | AC4: =+EDATE(AB4,1) -> 44743 | AD4: =+EDATE(AC4,1) -> 44774 | AE4: =+EDATE(AD4,1) -> 44805 | AF4: =+EDATE(AE4,1) -> 44835 | AG4: =+EDATE(AF4,1) -> 44866 | AH4: =+EDATE(AG4,1) -> 44896 | AI4: =+EDATE(AH4,1) -> 44927 | AJ4: =+EDATE(AI4,1) -> 44958 | ... FJ4: =+EDATE(FI4,1) -> 48914 | FK4: =+'3. TMDT'!K5 -> 45291 | FL4: =+'3. TMDT'!L5 -> 45382 | FM4: =+'3. TMDT'!M5 -> 45473 | FN4: =+'3. TMDT'!N5 -> 45565 | FO4: =+'3. TMDT'!O5 -> 45657 | FP4: =+'3. TMDT'!P5 -> 45747 | FQ4: =+'3. TMDT'!Q5 -> 45838 | FR4: =+'3. TMDT'!R5 -> 45930 | ... GY4: =+'3. TMDT'!AY5 -> 48944
C5: Tiến độ thu tiền nhà ở xã hội | R5: 0.3 | S5: 0.1 | T5: 0.1 | U5: 0.1 | V5: 0.1 | W5: 0.25 | X5: 0 | Y5: 0.05
C6: Tiến độ thu tiền nhà liền kề | R6: 0.3 | S6: 0.15 | T6: 0.15 | U6: 0.1 | V6: 0.25 | W6: 0 | X6: 0 | Y6: 0.05
B8: 1 | C8: Nhà ở xã hội 1 | I8: =C8 -> Nhà ở xã hội 1 | J8: 46388 | K8: 429.23496 | L8: 2787.24 | M8: 21461.748 | N8: 22500000 | O8: {=_xlfn.IFS( YEAR(R8)=2027,N8,YEAR(R8)=2028,N8*(1+'1. Tổng hợp'!$C$16),YEAR(R8)=2029,N8*(1+'1. Tổng hợp'!$C$16)^2, YEAR(R8)=2030,N8*(1+'1. Tổng hợp'!$C$16)^3,YEAR(R8)=2031,N8*(1+'1. Tổng hợp'!$C$16)^3)} -> 22500000 | P8: =M8*O8 -> 4.8288933e+11 | Q8: =+X8 -> 47119 | R8: =J8 -> 46388 | S8: =EDATE(R8,2) -> 46447 | T8: =EDATE(S8,2) -> 46508 | U8: =EDATE(T8,2) -> 46569 | V8: =EDATE(U8,2) -> 46631 | W8: =EDATE(V8,16) -> 47119 | X8: =W8 -> 47119 | Y8: =EDATE(X8,1) -> 47150 | Z8: =+P8-AA8 -> 0 | AA8: =SUM(AB8:FJ8) -> 482889330000 | AB8: =SUMIF($R8:$Y8,AB$4,$R$5:$Y$5)*$P8 -> 0 | AC8: =SUMIF($R8:$Y8,AC$4,$R$5:$Y$5)*$P8 -> 0 | AD8: =SUMIF($R8:$Y8,AD$4,$R$5:$Y$5)*$P8 -> 0 | AE8: =SUMIF($R8:$Y8,AE$4,$R$5:$Y$5)*$P8 -> 0 | AF8: =SUMIF($R8:$Y8,AF$4,$R$5:$Y$5)*$P8 -> 0 | AG8: =SUMIF($R8:$Y8,AG$4,$R$5:$Y$5)*$P8 -> 0 | AH8: =SUMIF($R8:$Y8,AH$4,$R$5:$Y$5)*$P8 -> 0 | AI8: =SUMIF($R8:$Y8,AI$4,$R$5:$Y$5)*$P8 -> 0 | ... FJ8: =SUMIF($R8:$Y8,FJ$4,$R$5:$Y$5)*$P8 -> 0 | FL8: =SUMIFS($AB8:$FF8,$AB$2:$FF$2,FL$4) -> 0 | FM8: =SUMIFS($AB8:$FF8,$AB$2:$FF$2,FM$4) -> 0 | FN8: =SUMIFS($AB8:$FF8,$AB$2:$FF$2,FN$4) -> 0 | FO8: =SUMIFS($AB8:$FF8,$AB$2:$FF$2,FO$4) -> 0 | FP8: =SUMIFS($AB8:$FF8,$AB$2:$FF$2,FP$4) -> 0 | FQ8: =SUMIFS($AB8:$FF8,$AB$2:$FF$2,FQ$4) -> 0 | FR8: =SUMIFS($AB8:$FF8,$AB$2:$FF$2,FR$4) -> 0 | FS8: =SUMIFS($AB8:$FF8,$AB$2:$FF$2,FS$4) -> 0 | ... GY8: =SUMIFS($AB8:$FF8,$AB$2:$FF$2,GY$4) -> 0
B9: 2 | C9: Nhà ở xã hội 2 | I9: =C9 -> Nhà ở xã hội 2 | J9: 46753 | K9: 349.12416 | L9: 2267.04 | M9: 17456.208 | N9: 22500000 | O9: {=_xlfn.IFS( YEAR(R9)=2027,N9,YEAR(R9)=2028,N9*(1+'1. Tổng hợp'!$C$16),YEAR(R9)=2029,N9*(1+'1. Tổng hợp'!$C$16)^2, YEAR(R9)=2030,N9*(1+'1. Tổng hợp'!$C$16)^3,YEAR(R9)=2031,N9*(1+'1. Tổng hợp'!$C$16)^3)} -> 22500000 | P9: =M9*O9 -> 392764680000 | Q9: =+X9 -> 47484 | R9: =J9 -> 46753 | S9: =EDATE(R9,2) -> 46813 | T9: =EDATE(S9,2) -> 46874 | U9: =EDATE(T9,2) -> 46935 | V9: =EDATE(U9,2) -> 46997 | W9: =EDATE(V9,16) -> 47484 | X9: =W9 -> 47484 | Y9: =EDATE(X9,1) -> 47515 | Z9: =+P9-AA9 -> 0 | AA9: =SUM(AB9:FJ9) -> 392764680000 | AB9: =SUMIF($R9:$Y9,AB$4,$R$5:$Y$5)*$P9 -> 0 | AC9: =SUMIF($R9:$Y9,AC$4,$R$5:$Y$5)*$P9 -> 0 | AD9: =SUMIF($R9:$Y9,AD$4,$R$5:$Y$5)*$P9 -> 0 | AE9: =SUMIF($R9:$Y9,AE$4,$R$5:$Y$5)*$P9 -> 0 | AF9: =SUMIF($R9:$Y9,AF$4,$R$5:$Y$5)*$P9 -> 0 | AG9: =SUMIF($R9:$Y9,AG$4,$R$5:$Y$5)*$P9 -> 0 | AH9: =SUMIF($R9:$Y9,AH$4,$R$5:$Y$5)*$P9 -> 0 | AI9: =SUMIF($R9:$Y9,AI$4,$R$5:$Y$5)*$P9 -> 0 | ... FJ9: =SUMIF($R9:$Y9,FJ$4,$R$5:$Y$5)*$P9 -> 0 | FL9: =SUMIFS($AB9:$FF9,$AB$2:$FF$2,FL$4) -> 0 | FM9: =SUMIFS($AB9:$FF9,$AB$2:$FF$2,FM$4) -> 0 | FN9: =SUMIFS($AB9:$FF9,$AB$2:$FF$2,FN$4) -> 0 | FO9: =SUMIFS($AB9:$FF9,$AB$2:$FF$2,FO$4) -> 0 | FP9: =SUMIFS($AB9:$FF9,$AB$2:$FF$2,FP$4) -> 0 | FQ9: =SUMIFS($AB9:$FF9,$AB$2:$FF$2,FQ$4) -> 0 | FR9: =SUMIFS($AB9:$FF9,$AB$2:$FF$2,FR$4) -> 0 | FS9: =SUMIFS($AB9:$FF9,$AB$2:$FF$2,FS$4) -> 0 | ... GY9: =SUMIFS($AB9:$FF9,$AB$2:$FF$2,GY$4) -> 0
B10: 3 | C10: Nhà ở xã hội 3 | I10: =C10 -> Nhà ở xã hội 3 | J10: 47119 | K10: 289.28592 | L10: 1878.48 | M10: 14464.296 | N10: 22500000 | O10: {=_xlfn.IFS( YEAR(R10)=2027,N10,YEAR(R10)=2028,N10*(1+'1. Tổng hợp'!$C$16),YEAR(R10)=2029,N10*(1+'1. Tổng hợp'!$C$16)^2, YEAR(R10)=2030,N10*(1+'1. Tổng hợp'!$C$16)^3,YEAR(R10)=2031,N10*(1+'1. Tổng hợp'!$C$16)^3)} -> 22500000 | P10: =M10*O10 -> 3.2544666e+11 | Q10: =+X10 -> 47849 | R10: =J10 -> 47119 | S10: =EDATE(R10,2) -> 47178 | T10: =EDATE(S10,2) -> 47239 | U10: =EDATE(T10,2) -> 47300 | V10: =EDATE(U10,2) -> 47362 | W10: =EDATE(V10,16) -> 47849 | X10: =W10 -> 47849 | Y10: =EDATE(X10,1) -> 47880 | Z10: =+P10-AA10 -> 0 | AA10: =SUM(AB10:FJ10) -> 3.2544666e+11 | AB10: =SUMIF($R10:$Y10,AB$4,$R$5:$Y$5)*$P10 -> 0 | AC10: =SUMIF($R10:$Y10,AC$4,$R$5:$Y$5)*$P10 -> 0 | AD10: =SUMIF($R10:$Y10,AD$4,$R$5:$Y$5)*$P10 -> 0 | AE10: =SUMIF($R10:$Y10,AE$4,$R$5:$Y$5)*$P10 -> 0 | AF10: =SUMIF($R10:$Y10,AF$4,$R$5:$Y$5)*$P10 -> 0 | AG10: =SUMIF($R10:$Y10,AG$4,$R$5:$Y$5)*$P10 -> 0 | AH10: =SUMIF($R10:$Y10,AH$4,$R$5:$Y$5)*$P10 -> 0 | AI10: =SUMIF($R10:$Y10,AI$4,$R$5:$Y$5)*$P10 -> 0 | ... FJ10: =SUMIF($R10:$Y10,FJ$4,$R$5:$Y$5)*$P10 -> 0 | FL10: =SUMIFS($AB10:$FF10,$AB$2:$FF$2,FL$4) -> 0 | FM10: =SUMIFS($AB10:$FF10,$AB$2:$FF$2,FM$4) -> 0 | FN10: =SUMIFS($AB10:$FF10,$AB$2:$FF$2,FN$4) -> 0 | FO10: =SUMIFS($AB10:$FF10,$AB$2:$FF$2,FO$4) -> 0 | FP10: =SUMIFS($AB10:$FF10,$AB$2:$FF$2,FP$4) -> 0 | FQ10: =SUMIFS($AB10:$FF10,$AB$2:$FF$2,FQ$4) -> 0 | FR10: =SUMIFS($AB10:$FF10,$AB$2:$FF$2,FR$4) -> 0 | FS10: =SUMIFS($AB10:$FF10,$AB$2:$FF$2,FS$4) -> 0 | ... GY10: =SUMIFS($AB10:$FF10,$AB$2:$FF$2,GY$4) -> 0
B11: 4 | C11: Liền kề 1 | I11: =C11 -> Liền kề 1 | J11: 46753 | K11: 51 | L11: 4320.5 | M11: 4320.5 | N11: 77500000 | O11: {=_xlfn.IFS( YEAR(R11)=2027,N11,YEAR(R11)=2028,N11*(1+'1. Tổng hợp'!$C$16),YEAR(R11)=2029,N11*(1+'1. Tổng hợp'!$C$16)^2, YEAR(R11)=2030,N11*(1+'1. Tổng hợp'!$C$16)^3,YEAR(R11)=2031,N11*(1+'1. Tổng hợp'!$C$16)^3)} -> 77500000 | P11: =M11*O11 -> 334838750000 | Q11: =+X11 -> 47119 | R11: =J11 -> 46753 | S11: =EDATE(R11,3) -> 46844 | T11: =EDATE(S11,3) -> 46935 | U11: =EDATE(T11,3) -> 47027 | V11: =EDATE(U11,3) -> 47119 | W11: =V11 -> 47119 | X11: =W11 -> 47119 | Y11: =EDATE(X11,1) -> 47150 | Z11: =+P11-AA11 -> 0 | AA11: =SUM(AB11:FJ11) -> 334838750000 | AB11: =SUMIF($R11:$Y11,AB$4,$R$5:$Y$5)*$P11 -> 0 | AC11: =SUMIF($R11:$Y11,AC$4,$R$5:$Y$5)*$P11 -> 0 | AD11: =SUMIF($R11:$Y11,AD$4,$R$5:$Y$5)*$P11 -> 0 | AE11: =SUMIF($R11:$Y11,AE$4,$R$5:$Y$5)*$P11 -> 0 | AF11: =SUMIF($R11:$Y11,AF$4,$R$5:$Y$5)*$P11 -> 0 | AG11: =SUMIF($R11:$Y11,AG$4,$R$5:$Y$5)*$P11 -> 0 | AH11: =SUMIF($R11:$Y11,AH$4,$R$5:$Y$5)*$P11 -> 0 | AI11: =SUMIF($R11:$Y11,AI$4,$R$5:$Y$5)*$P11 -> 0 | ... FJ11: =SUMIF($R11:$Y11,FJ$4,$R$5:$Y$5)*$P11 -> 0 | FL11: =SUMIFS($AB11:$FF11,$AB$2:$FF$2,FL$4) -> 0 | FM11: =SUMIFS($AB11:$FF11,$AB$2:$FF$2,FM$4) -> 0 | FN11: =SUMIFS($AB11:$FF11,$AB$2:$FF$2,FN$4) -> 0 | FO11: =SUMIFS($AB11:$FF11,$AB$2:$FF$2,FO$4) -> 0 | FP11: =SUMIFS($AB11:$FF11,$AB$2:$FF$2,FP$4) -> 0 | FQ11: =SUMIFS($AB11:$FF11,$AB$2:$FF$2,FQ$4) -> 0 | FR11: =SUMIFS($AB11:$FF11,$AB$2:$FF$2,FR$4) -> 0 | FS11: =SUMIFS($AB11:$FF11,$AB$2:$FF$2,FS$4) -> 0 | ... GY11: =SUMIFS($AB11:$FF11,$AB$2:$FF$2,GY$4) -> 0
B12: =P12=SUM(BE12:FJ12) -> TRUE | L12: =SUBTOTAL(9,L8:L11) -> 11253.26 | M12: =SUBTOTAL(9,M8:M11) -> 57702.752 | P12: =SUM(P8:P11) -> 1535939420000 | AB12: =SUM(AB8:AB11) -> 0 | AC12: =SUM(AC8:AC11) -> 0 | AD12: =SUM(AD8:AD11) -> 0 | AE12: =SUM(AE8:AE11) -> 0 | AF12: =SUM(AF8:AF11) -> 0 | AG12: =SUM(AG8:AG11) -> 0 | AH12: =SUM(AH8:AH11) -> 0 | AI12: =SUM(AI8:AI11) -> 0 | ... FJ12: =SUM(FJ8:FJ11) -> 0 | FL12: =SUM(FL8:FL11) -> 0 | FM12: =SUM(FM8:FM11) -> 0 | FN12: =SUM(FN8:FN11) -> 0 | FO12: =SUM(FO8:FO11) -> 0 | FP12: =SUM(FP8:FP11) -> 0 | FQ12: =SUM(FQ8:FQ11) -> 0 | FR12: =SUM(FR8:FR11) -> 0 | FS12: =SUM(FS8:FS11) -> 0 | ... GY12: =SUM(GY8:GY11) -> 0

Sheet 6. PBChiPhi
A1: BẢNG 6: PHÂN BỔ CHI PHÍ ĐẦU TƯ DỰ ÁN
A5: STT | B5: Nội dung | C5: Tỷ lệ phân bổ | D5: Tổng | E5: ='5. KHBH'!C8 -> Nhà ở xã hội 1 | F5: ='5. KHBH'!C9 -> Nhà ở xã hội 2 | G5: ='5. KHBH'!C10 -> Nhà ở xã hội 3 | H5: ='5. KHBH'!C11 -> Liền kề 1
A6: I | B6: Tiêu thức phân bổ
B7: Phân bổ các loại chi phí | D7: =SUM(E7:H7) -> 11253.26 | E7: ='5. KHBH'!L8 -> 2787.24 | F7: ='5. KHBH'!L9 -> 2267.04 | G7: ='5. KHBH'!L10 -> 1878.48 | H7: ='5. KHBH'!L11 -> 4320.5
B8: - Phân bổ theo diện tích ô đất | D8: =SUM(E8:H8) -> 1 | E8: =E7/$D$7 -> 0.24768289 | F8: =F7/$D$7 -> 0.20145629 | G8: =G7/$D$7 -> 0.16692763 | H8: =H7/$D$7 -> 0.38393319
A9: II | B9: Phân bổ chi phí | C9: Ghi chú | D9: Tổng
A10: 1 | B10: ='2. CPxaydung'!B6 -> Chi phí xây dựng, thiết bị | D10: =SUM(D11:D13) -> 8.6824028e+11 | E10: =SUM(E11:E13) -> 3.1283242e+11 | F10: =SUM(F11:F13) -> 2.5444655e+11 | G10: =SUM(G11:G13) -> 2.1083561e+11 | H10: =SUM(H11:H13) -> 9.0125701e+10 | I10: =D10-'3. TMDT'!E7 -> 0
B11: Chi phí xây dựng và thiết bị phần hạ tầng kỹ thuật | D11: ='2. CPxaydung'!G7 -> 2.8275455e+10 | E11: =$D$11*E8 -> 7.0033464e+09 | F11: =$D$11*F8 -> 5.6962681e+09 | G11: =$D$11*G8 -> 4.7199546e+09 | H11: =$D$11*H8 -> 1.0855885e+10
B12: Chi phí xây dựng và thiết bị phần nhà ở, thương mại dịch vụ, công trình công cộng và y tế, giáo dục | D12: ='2. CPxaydung'!G8 -> 7.8697364e+11 | E12: =$D$12*E20/SUM($E$20:$H$20) -> 2.9270406e+11 | F12: =$D$12*F20/SUM($E$20:$H$20) -> 2.3807488e+11 | G12: =$D$12*G20/SUM($E$20:$H$20) -> 1.9726996e+11 | H12: =$D$12*H20/SUM($E$20:$H$20) -> 5.8924739e+10
B13: Chi phí quản lý dự án, chi phí tư vấn và chi phí khác | D13: ='2. CPxaydung'!G9 -> 5.2991191e+10 | E13: =$D$13*E8 -> 1.3125012e+10 | F13: =$D$13*F8 -> 1.0675409e+10 | G13: =$D$13*G8 -> 8.8456938e+09 | H13: =$D$13*H8 -> 2.0345077e+10
A14: 2 | B14: ='2. CPxaydung'!B10 -> Chi phí quản lý dự án + tư vấn + khác | D14: ='2. CPxaydung'!G10 -> 0 | E14: =$D14*E$8 -> 0 | F14: =$D14*F$8 -> 0 | G14: =$D14*G$8 -> 0 | H14: =$D14*H$8 -> 0 | I14: ='3. TMDT'!E8-'6. PBChiPhi'!D14 -> 0
A15: 3 | B15: ='2. CPxaydung'!B11 -> Chi phí dự phòng | D15: ='2. CPxaydung'!G11 -> 1.3093411e+11 | E15: =$D15*E$8 -> 3.2430139e+10 | F15: =$D15*F$8 -> 2.6377499e+10 | G15: =$D15*G$8 -> 2.185652e+10 | H15: =$D15*H$8 -> 5.0269949e+10 | I15: =D15-'3. TMDT'!E9 -> 0
A16: 4 | B16: ='3. TMDT'!B10 -> Chi phí GPMB và tiền sử dụng đất | D16: ='3. TMDT'!E10 -> 43014372094 | E16: =$D16*E$8 -> 1.0653924e+10 | F16: =$D16*F$8 -> 8.6655158e+09 | G16: =$D16*G$8 -> 7.1802871e+09 | H16: =$D16*H$8 -> 1.6514645e+10 | I16: =D16-'3. TMDT'!E10 -> 0
A17: 5 | B17: ='3. TMDT'!B14 -> Lãi vay trong giai đoạn xây dựng | D17: ='3. TMDT'!E14 -> 4.501737e+10 | E17: =$D17*E$8 -> 1.1150032e+10 | F17: =$D17*F$8 -> 9.0690323e+09 | G17: =$D17*G$8 -> 7.5146428e+09 | H17: =$D17*H$8 -> 1.7283662e+10 | I17: =D17-'3. TMDT'!E14 -> 0
B19: Giá vốn bao gồm lãi vay | D19: =SUM(E19:H19) -> 1.0872061e+12 | E19: =E10+SUM(E14:E17) -> 3.6706651e+11 | F19: =F10+SUM(F14:F17) -> 2.985586e+11 | G19: =G10+SUM(G14:G17) -> 2.4738706e+11 | H19: =H10+SUM(H14:H17) -> 1.7419396e+11
B20: Diện tích thương phẩm | E20: ='5. KHBH'!M8 -> 21461.748 | F20: ='5. KHBH'!M9 -> 17456.208 | G20: ='5. KHBH'!M10 -> 14464.296 | H20: ='5. KHBH'!M11 -> 4320.5
B21: Giá vốn/m2 đất thương phẩm | E21: =E19/E20 -> 17103291 | F21: =F19/F20 -> 17103291 | G21: =G19/G20 -> 17103291 | H21: =H19/H20 -> 40318009
B22: Phân bổ chi phí bán hàng | D22: ='7. P&L TOÀN DỰ ÁN'!C19 -> 2.7926171e+10 | E22: =$D$22*'5. KHBH'!P8/'5. KHBH'!$P$12 -> 8.779806e+09 | F22: =$D$22*'5. KHBH'!P9/'5. KHBH'!$P$12 -> 7141176000 | G22: =$D$22*'5. KHBH'!P10/'5. KHBH'!$P$12 -> 5.917212e+09 | H22: =$D$22*'5. KHBH'!P11/'5. KHBH'!$P$12 -> 6.0879773e+09
B23: Chi phí bán hàng/m2 đất thương phẩm | E23: =E22/E20 -> 409090.91 | F23: =F22/F20 -> 409090.91 | G23: =G22/G20 -> 409090.91 | H23: =H22/H20 -> 1409090.9
B24: Phân bổ chi phí lãi vay | D24: ='7. P&L TOÀN DỰ ÁN'!C21 -> 3.4643888e+10 | E24: =$D$24*'5. KHBH'!P8/'5. KHBH'!$P$12 -> 1.0891812e+10 | F24: =$D$24*'5. KHBH'!P9/'5. KHBH'!$P$12 -> 8.8590054e+09 | G24: =$D$24*'5. KHBH'!P10/'5. KHBH'!$P$12 -> 7.3406135e+09 | H24: =$D$24*'5. KHBH'!P11/'5. KHBH'!$P$12 -> 7.5524568e+09
B25: Chi phí lãi vay/m2 đất thương phẩm | E25: =E24/E20 -> 507498.85 | F25: =F24/F20 -> 507498.85 | G25: =G24/G20 -> 507498.85 | H25: =H24/H20 -> 1748051.6
B26: Phân bổ chi phí quản lý | D26: ='7. P&L TOÀN DỰ ÁN'!C20 -> 2.7926171e+10 | E26: =$D$26*'5. KHBH'!P8/'5. KHBH'!$P$12 -> 8.779806e+09 | F26: =$D$26*'5. KHBH'!P9/'5. KHBH'!$P$12 -> 7141176000 | G26: =$D$26*'5. KHBH'!P10/'5. KHBH'!$P$12 -> 5.917212e+09 | H26: =$D$26*'5. KHBH'!P11/'5. KHBH'!$P$12 -> 6.0879773e+09
E27: =E26/E20 -> 409090.91 | F27: =F26/F20 -> 409090.91 | G27: =G26/G20 -> 409090.91 | H27: =H26/H20 -> 1409090.9
B28: Tổng giá vốn phân bổ (chưa bao gồm VAT) | E28: =E21+E23+E25+E27 -> 18428971 | F28: =F21+F23+F25+F27 -> 18428971 | G28: =G21+G23+G25+G27 -> 18428971 | H28: =H21+H23+H25+H27 -> 44884242
F29: =F28*1.1 -> 20271868
E30: =+E21+E23+E25+E27 -> 18428971 | F30: =F29*1.1 -> 22299055
E31: =+E30*1.1 -> 20271868
E32: =+E31*1.1 -> 22299055

Sheet 7. P&L TOÀN DỰ ÁN
A1: KẾT QUẢ KINH DOANH TOÀN DỰ ÁN
C2: ĐVT: VNĐ | E2: =+'5. KHBH'!AB2 -> 44742 | F2: =+'5. KHBH'!AC2 -> 44834 | G2: =+'5. KHBH'!AD2 -> 44834 | H2: =+'5. KHBH'!AE2 -> 44834 | I2: =+'5. KHBH'!AF2 -> 44926 | J2: =+'5. KHBH'!AG2 -> 44926 | K2: =+'5. KHBH'!AH2 -> 44926 | L2: =+'5. KHBH'!AI2 -> 45016 | ... EM2: =+'5. KHBH'!FJ2 -> 48944
A3: TT | B3: Nội dung | C3: Tổng | D3: Diện tích bán sản phẩm | E3: =+'5. KHBH'!AB4 -> 44713 | F3: =+'5. KHBH'!AC4 -> 44743 | G3: =+'5. KHBH'!AD4 -> 44774 | H3: =+'5. KHBH'!AE4 -> 44805 | I3: =+'5. KHBH'!AF4 -> 44835 | J3: =+'5. KHBH'!AG4 -> 44866 | K3: =+'5. KHBH'!AH4 -> 44896 | L3: =+'5. KHBH'!AI4 -> 44927 | ... GB3: =+'5. KHBH'!GY4 -> 48944
A4: I | B4: Doanh thu từ bán và chuyển nhượng bất động sản | C4: =SUM(C5:C8) -> 1.3963086e+12 | D4: =SUM(D5:D8) -> 57702.752 | E4: =SUM(#REF!) -> #REF! | F4: =SUM(#REF!) -> #REF! | G4: =SUM(#REF!) -> #REF! | H4: =SUM(#REF!) -> #REF! | I4: =SUM(#REF!) -> #REF! | J4: =SUM(#REF!) -> #REF! | K4: =SUM(#REF!) -> #REF! | L4: =SUM(#REF!) -> #REF! | ... EM4: =SUM(#REF!) -> #REF! | EN4: =SUM(EN5:EN8) -> 0 | EO4: =SUM(EO5:EO8) -> 0 | EP4: =SUM(EP5:EP8) -> 0 | EQ4: =SUM(EQ5:EQ8) -> 0 | ER4: =SUM(ER5:ER8) -> 0 | ES4: =SUM(ES5:ES8) -> 0 | ET4: =SUM(ET5:ET8) -> 0 | EU4: =SUM(EU5:EU8) -> 0 | ... GB4: =SUM(GB5:GB8) -> 0
A5: 1 | B5: ='5. KHBH'!C8 -> Nhà ở xã hội 1 | C5: =SUM(EN5:GB5) -> 4.389903e+11 | D5: =SUMIF('5. KHBH'!$I$8:$I$11,B5,'5. KHBH'!$M$8:$M$11) -> 21461.748 | E5: =SUMIFS('5. KHBH'!$P$8:$P$11,'5. KHBH'!$Q$8:$Q$11,'7. P&L TOÀN DỰ ÁN'!E$3,'5. KHBH'!$I$8:$I$11,'7. P&L TOÀN DỰ ÁN'!$B5)/1.1 -> 0 | F5: =SUMIFS('5. KHBH'!$P$8:$P$11,'5. KHBH'!$Q$8:$Q$11,'7. P&L TOÀN DỰ ÁN'!F$3,'5. KHBH'!$I$8:$I$11,'7. P&L TOÀN DỰ ÁN'!$B5)/1.1 -> 0 | G5: =SUMIFS('5. KHBH'!$P$8:$P$11,'5. KHBH'!$Q$8:$Q$11,'7. P&L TOÀN DỰ ÁN'!G$3,'5. KHBH'!$I$8:$I$11,'7. P&L TOÀN DỰ ÁN'!$B5)/1.1 -> 0 | H5: =SUMIFS('5. KHBH'!$P$8:$P$11,'5. KHBH'!$Q$8:$Q$11,'7. P&L TOÀN DỰ ÁN'!H$3,'5. KHBH'!$I$8:$I$11,'7. P&L TOÀN DỰ ÁN'!$B5)/1.1 -> 0 | I5: =SUMIFS('5. KHBH'!$P$8:$P$11,'5. KHBH'!$Q$8:$Q$11,'7. P&L TOÀN DỰ ÁN'!I$3,'5. KHBH'!$I$8:$I$11,'7. P&L TOÀN DỰ ÁN'!$B5)/1.1 -> 0 | J5: =SUMIFS('5. KHBH'!$P$8:$P$11,'5. KHBH'!$Q$8:$Q$11,'7. P&L TOÀN DỰ ÁN'!J$3,'5. KHBH'!$I$8:$I$11,'7. P&L TOÀN DỰ ÁN'!$B5)/1.1 -> 0 | K5: =SUMIFS('5. KHBH'!$P$8:$P$11,'5. KHBH'!$Q$8:$Q$11,'7. P&L TOÀN DỰ ÁN'!K$3,'5. KHBH'!$I$8:$I$11,'7. P&L TOÀN DỰ ÁN'!$B5)/1.1 -> 0 | L5: =SUMIFS('5. KHBH'!$P$8:$P$11,'5. KHBH'!$Q$8:$Q$11,'7. P&L TOÀN DỰ ÁN'!L$3,'5. KHBH'!$I$8:$I$11,'7. P&L TOÀN DỰ ÁN'!$B5)/1.1 -> 0 | ... EM5: =SUMIFS('5. KHBH'!$P$8:$P$11,'5. KHBH'!$Q$8:$Q$11,'7. P&L TOÀN DỰ ÁN'!EM$3,'5. KHBH'!$I$8:$I$11,'7. P&L TOÀN DỰ ÁN'!$B5)/1.1 -> 0 | EN5: =SUMIFS($E5:$EM5,$E$2:$EM$2,EN$3) -> 0 | EO5: =SUMIFS($E5:$EM5,$E$2:$EM$2,EO$3) -> 0 | EP5: =SUMIFS($E5:$EM5,$E$2:$EM$2,EP$3) -> 0 | EQ5: =SUMIFS($E5:$EM5,$E$2:$EM$2,EQ$3) -> 0 | ER5: =SUMIFS($E5:$EM5,$E$2:$EM$2,ER$3) -> 0 | ES5: =SUMIFS($E5:$EM5,$E$2:$EM$2,ES$3) -> 0 | ET5: =SUMIFS($E5:$EM5,$E$2:$EM$2,ET$3) -> 0 | EU5: =SUMIFS($E5:$EM5,$E$2:$EM$2,EU$3) -> 0 | ... GB5: =SUMIFS($E5:$EM5,$E$2:$EM$2,GB$3) -> 0
A6: =A5+1 -> 2 | B6: ='5. KHBH'!C9 -> Nhà ở xã hội 2 | C6: =SUM(EN6:GB6) -> 357058800000 | D6: =SUMIF('5. KHBH'!$I$8:$I$11,B6,'5. KHBH'!$M$8:$M$11) -> 17456.208 | E6: =SUMIFS('5. KHBH'!$P$8:$P$11,'5. KHBH'!$Q$8:$Q$11,'7. P&L TOÀN DỰ ÁN'!E$3,'5. KHBH'!$I$8:$I$11,'7. P&L TOÀN DỰ ÁN'!$B6)/1.1 -> 0 | F6: =SUMIFS('5. KHBH'!$P$8:$P$11,'5. KHBH'!$Q$8:$Q$11,'7. P&L TOÀN DỰ ÁN'!F$3,'5. KHBH'!$I$8:$I$11,'7. P&L TOÀN DỰ ÁN'!$B6)/1.1 -> 0 | G6: =SUMIFS('5. KHBH'!$P$8:$P$11,'5. KHBH'!$Q$8:$Q$11,'7. P&L TOÀN DỰ ÁN'!G$3,'5. KHBH'!$I$8:$I$11,'7. P&L TOÀN DỰ ÁN'!$B6)/1.1 -> 0 | H6: =SUMIFS('5. KHBH'!$P$8:$P$11,'5. KHBH'!$Q$8:$Q$11,'7. P&L TOÀN DỰ ÁN'!H$3,'5. KHBH'!$I$8:$I$11,'7. P&L TOÀN DỰ ÁN'!$B6)/1.1 -> 0 | I6: =SUMIFS('5. KHBH'!$P$8:$P$11,'5. KHBH'!$Q$8:$Q$11,'7. P&L TOÀN DỰ ÁN'!I$3,'5. KHBH'!$I$8:$I$11,'7. P&L TOÀN DỰ ÁN'!$B6)/1.1 -> 0 | J6: =SUMIFS('5. KHBH'!$P$8:$P$11,'5. KHBH'!$Q$8:$Q$11,'7. P&L TOÀN DỰ ÁN'!J$3,'5. KHBH'!$I$8:$I$11,'7. P&L TOÀN DỰ ÁN'!$B6)/1.1 -> 0 | K6: =SUMIFS('5. KHBH'!$P$8:$P$11,'5. KHBH'!$Q$8:$Q$11,'7. P&L TOÀN DỰ ÁN'!K$3,'5. KHBH'!$I$8:$I$11,'7. P&L TOÀN DỰ ÁN'!$B6)/1.1 -> 0 | L6: =SUMIFS('5. KHBH'!$P$8:$P$11,'5. KHBH'!$Q$8:$Q$11,'7. P&L TOÀN DỰ ÁN'!L$3,'5. KHBH'!$I$8:$I$11,'7. P&L TOÀN DỰ ÁN'!$B6)/1.1 -> 0 | ... EM6: =SUMIFS('5. KHBH'!$P$8:$P$11,'5. KHBH'!$Q$8:$Q$11,'7. P&L TOÀN DỰ ÁN'!EM$3,'5. KHBH'!$I$8:$I$11,'7. P&L TOÀN DỰ ÁN'!$B6)/1.1 -> 0 | EN6: =SUMIFS($E6:$EM6,$E$2:$EM$2,EN$3) -> 0 | EO6: =SUMIFS($E6:$EM6,$E$2:$EM$2,EO$3) -> 0 | EP6: =SUMIFS($E6:$EM6,$E$2:$EM$2,EP$3) -> 0 | EQ6: =SUMIFS($E6:$EM6,$E$2:$EM$2,EQ$3) -> 0 | ER6: =SUMIFS($E6:$EM6,$E$2:$EM$2,ER$3) -> 0 | ES6: =SUMIFS($E6:$EM6,$E$2:$EM$2,ES$3) -> 0 | ET6: =SUMIFS($E6:$EM6,$E$2:$EM$2,ET$3) -> 0 | EU6: =SUMIFS($E6:$EM6,$E$2:$EM$2,EU$3) -> 0 | ... GB6: =SUMIFS($E6:$EM6,$E$2:$EM$2,GB$3) -> 0
A7: 3 | B7: ='5. KHBH'!C10 -> Nhà ở xã hội 3 | C7: =SUM(EN7:GB7) -> 2.958606e+11 | D7: =SUMIF('5. KHBH'!$I$8:$I$11,B7,'5. KHBH'!$M$8:$M$11) -> 14464.296 | E7: =SUMIFS('5. KHBH'!$P$8:$P$11,'5. KHBH'!$Q$8:$Q$11,'7. P&L TOÀN DỰ ÁN'!E$3,'5. KHBH'!$I$8:$I$11,'7. P&L TOÀN DỰ ÁN'!$B7)/1.1 -> 0 | F7: =SUMIFS('5. KHBH'!$P$8:$P$11,'5. KHBH'!$Q$8:$Q$11,'7. P&L TOÀN DỰ ÁN'!F$3,'5. KHBH'!$I$8:$I$11,'7. P&L TOÀN DỰ ÁN'!$B7)/1.1 -> 0 | G7: =SUMIFS('5. KHBH'!$P$8:$P$11,'5. KHBH'!$Q$8:$Q$11,'7. P&L TOÀN DỰ ÁN'!G$3,'5. KHBH'!$I$8:$I$11,'7. P&L TOÀN DỰ ÁN'!$B7)/1.1 -> 0 | H7: =SUMIFS('5. KHBH'!$P$8:$P$11,'5. KHBH'!$Q$8:$Q$11,'7. P&L TOÀN DỰ ÁN'!H$3,'5. KHBH'!$I$8:$I$11,'7. P&L TOÀN DỰ ÁN'!$B7)/1.1 -> 0 | I7: =SUMIFS('5. KHBH'!$P$8:$P$11,'5. KHBH'!$Q$8:$Q$11,'7. P&L TOÀN DỰ ÁN'!I$3,'5. KHBH'!$I$8:$I$11,'7. P&L TOÀN DỰ ÁN'!$B7)/1.1 -> 0 | J7: =SUMIFS('5. KHBH'!$P$8:$P$11,'5. KHBH'!$Q$8:$Q$11,'7. P&L TOÀN DỰ ÁN'!J$3,'5. KHBH'!$I$8:$I$11,'7. P&L TOÀN DỰ ÁN'!$B7)/1.1 -> 0 | K7: =SUMIFS('5. KHBH'!$P$8:$P$11,'5. KHBH'!$Q$8:$Q$11,'7. P&L TOÀN DỰ ÁN'!K$3,'5. KHBH'!$I$8:$I$11,'7. P&L TOÀN DỰ ÁN'!$B7)/1.1 -> 0 | L7: =SUMIFS('5. KHBH'!$P$8:$P$11,'5. KHBH'!$Q$8:$Q$11,'7. P&L TOÀN DỰ ÁN'!L$3,'5. KHBH'!$I$8:$I$11,'7. P&L TOÀN DỰ ÁN'!$B7)/1.1 -> 0 | ... EM7: =SUMIFS('5. KHBH'!$P$8:$P$11,'5. KHBH'!$Q$8:$Q$11,'7. P&L TOÀN DỰ ÁN'!EM$3,'5. KHBH'!$I$8:$I$11,'7. P&L TOÀN DỰ ÁN'!$B7)/1.1 -> 0 | EN7: =SUMIFS($E7:$EM7,$E$2:$EM$2,EN$3) -> 0 | EO7: =SUMIFS($E7:$EM7,$E$2:$EM$2,EO$3) -> 0 | EP7: =SUMIFS($E7:$EM7,$E$2:$EM$2,EP$3) -> 0 | EQ7: =SUMIFS($E7:$EM7,$E$2:$EM$2,EQ$3) -> 0 | ER7: =SUMIFS($E7:$EM7,$E$2:$EM$2,ER$3) -> 0 | ES7: =SUMIFS($E7:$EM7,$E$2:$EM$2,ES$3) -> 0 | ET7: =SUMIFS($E7:$EM7,$E$2:$EM$2,ET$3) -> 0 | EU7: =SUMIFS($E7:$EM7,$E$2:$EM$2,EU$3) -> 0 | ... GB7: =SUMIFS($E7:$EM7,$E$2:$EM$2,GB$3) -> 0
A8: 4 | B8: ='5. KHBH'!C11 -> Liền kề 1 | C8: =SUM(EN8:GB8) -> 3.0439886e+11 | D8: =SUMIF('5. KHBH'!$I$8:$I$11,B8,'5. KHBH'!$M$8:$M$11) -> 4320.5 | E8: =SUMIFS('5. KHBH'!$P$8:$P$11,'5. KHBH'!$Q$8:$Q$11,'7. P&L TOÀN DỰ ÁN'!E$3,'5. KHBH'!$I$8:$I$11,'7. P&L TOÀN DỰ ÁN'!$B8)/1.1 -> 0 | F8: =SUMIFS('5. KHBH'!$P$8:$P$11,'5. KHBH'!$Q$8:$Q$11,'7. P&L TOÀN DỰ ÁN'!F$3,'5. KHBH'!$I$8:$I$11,'7. P&L TOÀN DỰ ÁN'!$B8)/1.1 -> 0 | G8: =SUMIFS('5. KHBH'!$P$8:$P$11,'5. KHBH'!$Q$8:$Q$11,'7. P&L TOÀN DỰ ÁN'!G$3,'5. KHBH'!$I$8:$I$11,'7. P&L TOÀN DỰ ÁN'!$B8)/1.1 -> 0 | H8: =SUMIFS('5. KHBH'!$P$8:$P$11,'5. KHBH'!$Q$8:$Q$11,'7. P&L TOÀN DỰ ÁN'!H$3,'5. KHBH'!$I$8:$I$11,'7. P&L TOÀN DỰ ÁN'!$B8)/1.1 -> 0 | I8: =SUMIFS('5. KHBH'!$P$8:$P$11,'5. KHBH'!$Q$8:$Q$11,'7. P&L TOÀN DỰ ÁN'!I$3,'5. KHBH'!$I$8:$I$11,'7. P&L TOÀN DỰ ÁN'!$B8)/1.1 -> 0 | J8: =SUMIFS('5. KHBH'!$P$8:$P$11,'5. KHBH'!$Q$8:$Q$11,'7. P&L TOÀN DỰ ÁN'!J$3,'5. KHBH'!$I$8:$I$11,'7. P&L TOÀN DỰ ÁN'!$B8)/1.1 -> 0 | K8: =SUMIFS('5. KHBH'!$P$8:$P$11,'5. KHBH'!$Q$8:$Q$11,'7. P&L TOÀN DỰ ÁN'!K$3,'5. KHBH'!$I$8:$I$11,'7. P&L TOÀN DỰ ÁN'!$B8)/1.1 -> 0 | L8: =SUMIFS('5. KHBH'!$P$8:$P$11,'5. KHBH'!$Q$8:$Q$11,'7. P&L TOÀN DỰ ÁN'!L$3,'5. KHBH'!$I$8:$I$11,'7. P&L TOÀN DỰ ÁN'!$B8)/1.1 -> 0 | ... EM8: =SUMIFS('5. KHBH'!$P$8:$P$11,'5. KHBH'!$Q$8:$Q$11,'7. P&L TOÀN DỰ ÁN'!EM$3,'5. KHBH'!$I$8:$I$11,'7. P&L TOÀN DỰ ÁN'!$B8)/1.1 -> 0 | EN8: =SUMIFS($E8:$EM8,$E$2:$EM$2,EN$3) -> 0 | EO8: =SUMIFS($E8:$EM8,$E$2:$EM$2,EO$3) -> 0 | EP8: =SUMIFS($E8:$EM8,$E$2:$EM$2,EP$3) -> 0 | EQ8: =SUMIFS($E8:$EM8,$E$2:$EM$2,EQ$3) -> 0 | ER8: =SUMIFS($E8:$EM8,$E$2:$EM$2,ER$3) -> 0 | ES8: =SUMIFS($E8:$EM8,$E$2:$EM$2,ES$3) -> 0 | ET8: =SUMIFS($E8:$EM8,$E$2:$EM$2,ET$3) -> 0 | EU8: =SUMIFS($E8:$EM8,$E$2:$EM$2,EU$3) -> 0 | ... GB8: =SUMIFS($E8:$EM8,$E$2:$EM$2,GB$3) -> 0
A9: II | B9: Giá vốn bán hàng | C9: =SUM(C10:C13) -> 1.0872061e+12 | D9: =SUM(D10:D13) -> 57702.752 | EN9: =SUM(EN10:EN13) -> 0 | EO9: =SUM(EO10:EO13) -> 0 | EP9: =SUM(EP10:EP13) -> 0 | EQ9: =SUM(EQ10:EQ13) -> 0 | ER9: =SUM(ER10:ER13) -> 0 | ES9: =SUM(ES10:ES13) -> 0 | ET9: =SUM(ET10:ET13) -> 0 | EU9: =SUM(EU10:EU13) -> 0 | ... GB9: =SUM(GB10:GB13) -> 0
A10: =A5 -> 1 | B10: =B5 -> Nhà ở xã hội 1 | C10: =SUMIFS('6. PBChiPhi'!$E$19:$H$19,'6. PBChiPhi'!$E$5:$H$5,'7. P&L TOÀN DỰ ÁN'!$B10) -> 3.6706651e+11 | D10: =SUMIF('5. KHBH'!$I$8:$I$11,B5,'5. KHBH'!$M$8:$M$11) -> 21461.748 | EN10: =+EN5*$C10/$C5 -> 0 | EO10: =+EO5*$C10/$C5 -> 0 | EP10: =+EP5*$C10/$C5 -> 0 | EQ10: =+EQ5*$C10/$C5 -> 0 | ER10: =+ER5*$C10/$C5 -> 0 | ES10: =+ES5*$C10/$C5 -> 0 | ET10: =+ET5*$C10/$C5 -> 0 | EU10: =+EU5*$C10/$C5 -> 0 | ... GB10: =+GB5*$C10/$C5 -> 0
A11: =A6 -> 2 | B11: =B6 -> Nhà ở xã hội 2 | C11: =SUMIFS('6. PBChiPhi'!$E$19:$H$19,'6. PBChiPhi'!$E$5:$H$5,'7. P&L TOÀN DỰ ÁN'!$B11) -> 2.985586e+11 | D11: =SUMIF('5. KHBH'!$I$8:$I$11,B6,'5. KHBH'!$M$8:$M$11) -> 17456.208 | EN11: =+EN6*$C11/$C6 -> 0 | EO11: =+EO6*$C11/$C6 -> 0 | EP11: =+EP6*$C11/$C6 -> 0 | EQ11: =+EQ6*$C11/$C6 -> 0 | ER11: =+ER6*$C11/$C6 -> 0 | ES11: =+ES6*$C11/$C6 -> 0 | ET11: =+ET6*$C11/$C6 -> 0 | EU11: =+EU6*$C11/$C6 -> 0 | ... GB11: =+GB6*$C11/$C6 -> 0
A12: =A7 -> 3 | B12: =B7 -> Nhà ở xã hội 3 | C12: =SUMIFS('6. PBChiPhi'!$E$19:$H$19,'6. PBChiPhi'!$E$5:$H$5,'7. P&L TOÀN DỰ ÁN'!$B12) -> 2.4738706e+11 | D12: =SUMIF('5. KHBH'!$I$8:$I$11,B7,'5. KHBH'!$M$8:$M$11) -> 14464.296 | EN12: =+EN7*$C12/$C7 -> 0 | EO12: =+EO7*$C12/$C7 -> 0 | EP12: =+EP7*$C12/$C7 -> 0 | EQ12: =+EQ7*$C12/$C7 -> 0 | ER12: =+ER7*$C12/$C7 -> 0 | ES12: =+ES7*$C12/$C7 -> 0 | ET12: =+ET7*$C12/$C7 -> 0 | EU12: =+EU7*$C12/$C7 -> 0 | ... GB12: =+GB7*$C12/$C7 -> 0
A13: =A8 -> 4 | B13: =B8 -> Liền kề 1 | C13: =SUMIFS('6. PBChiPhi'!$E$19:$H$19,'6. PBChiPhi'!$E$5:$H$5,'7. P&L TOÀN DỰ ÁN'!$B13) -> 1.7419396e+11 | D13: =SUMIF('5. KHBH'!$I$8:$I$11,B8,'5. KHBH'!$M$8:$M$11) -> 4320.5 | EN13: =+EN8*$C13/$C8 -> 0 | EO13: =+EO8*$C13/$C8 -> 0 | EP13: =+EP8*$C13/$C8 -> 0 | EQ13: =+EQ8*$C13/$C8 -> 0 | ER13: =+ER8*$C13/$C8 -> 0 | ES13: =+ES8*$C13/$C8 -> 0 | ET13: =+ET8*$C13/$C8 -> 0 | EU13: =+EU8*$C13/$C8 -> 0 | ... GB13: =+GB8*$C13/$C8 -> 0
A14: III | B14: Lợi nhuận gộp | C14: =SUM(C15:C18) -> 3.0910243e+11 | D14: =SUM(D15:D18) -> 57702.752 | EN14: =SUM(EN15:EN18) -> 0 | EO14: =SUM(EO15:EO18) -> 0 | EP14: =SUM(EP15:EP18) -> 0 | EQ14: =SUM(EQ15:EQ18) -> 0 | ER14: =SUM(ER15:ER18) -> 0 | ES14: =SUM(ES15:ES18) -> 0 | ET14: =SUM(ET15:ET18) -> 0 | EU14: =SUM(EU15:EU18) -> 0 | ... GB14: =SUM(GB15:GB18) -> 0
A15: =A10 -> 1 | B15: =B5 -> Nhà ở xã hội 1 | C15: =SUM(EN15:GB15) -> 7.1923785e+10 | D15: =SUMIF('5. KHBH'!$I$8:$I$11,B5,'5. KHBH'!$M$8:$M$11) -> 21461.748 | EN15: =+EN5-EN10 -> 0 | EO15: =+EO5-EO10 -> 0 | EP15: =+EP5-EP10 -> 0 | EQ15: =+EQ5-EQ10 -> 0 | ER15: =+ER5-ER10 -> 0 | ES15: =+ES5-ES10 -> 0 | ET15: =+ET5-ET10 -> 0 | EU15: =+EU5-EU10 -> 0 | ... GB15: =+GB5-GB10 -> 0
A16: =A11 -> 2 | B16: =B6 -> Nhà ở xã hội 2 | C16: =SUM(EN16:GB16) -> 5.85002e+10 | D16: =SUMIF('5. KHBH'!$I$8:$I$11,B6,'5. KHBH'!$M$8:$M$11) -> 17456.208 | EN16: =+EN6-EN11 -> 0 | EO16: =+EO6-EO11 -> 0 | EP16: =+EP6-EP11 -> 0 | EQ16: =+EQ6-EQ11 -> 0 | ER16: =+ER6-ER11 -> 0 | ES16: =+ES6-ES11 -> 0 | ET16: =+ET6-ET11 -> 0 | EU16: =+EU6-EU11 -> 0 | ... GB16: =+GB6-GB11 -> 0
A17: =A12 -> 3 | B17: =B7 -> Nhà ở xã hội 3 | C17: =SUM(EN17:GB17) -> 4.8473541e+10 | D17: =SUMIF('5. KHBH'!$I$8:$I$11,B7,'5. KHBH'!$M$8:$M$11) -> 14464.296 | EN17: =+EN7-EN12 -> 0 | EO17: =+EO7-EO12 -> 0 | EP17: =+EP7-EP12 -> 0 | EQ17: =+EQ7-EQ12 -> 0 | ER17: =+ER7-ER12 -> 0 | ES17: =+ES7-ES12 -> 0 | ET17: =+ET7-ET12 -> 0 | EU17: =+EU7-EU12 -> 0 | ... GB17: =+GB7-GB12 -> 0
A18: =A13 -> 4 | B18: =B8 -> Liền kề 1 | C18: =SUM(EN18:GB18) -> 1.3020491e+11 | D18: =SUMIF('5. KHBH'!$I$8:$I$11,B8,'5. KHBH'!$M$8:$M$11) -> 4320.5 | EN18: =+EN8-EN13 -> 0 | EO18: =+EO8-EO13 -> 0 | EP18: =+EP8-EP13 -> 0 | EQ18: =+EQ8-EQ13 -> 0 | ER18: =+ER8-ER13 -> 0 | ES18: =+ES8-ES13 -> 0 | ET18: =+ET8-ET13 -> 0 | EU18: =+EU8-EU13 -> 0 | ... GB18: =+GB8-GB13 -> 0
A19: IV | B19: ='8. Hiệu quả dự án và CĐT'!B10 -> Chi phí bán hàng | C19: =(C4)*'1. Tổng hợp'!$D$19 -> 2.7926171e+10 | EN19: =+EN4*$C$19/$C$4 -> 0 | EO19: =+EO4*$C$19/$C$4 -> 0 | EP19: =+EP4*$C$19/$C$4 -> 0 | EQ19: =+EQ4*$C$19/$C$4 -> 0 | ER19: =+ER4*$C$19/$C$4 -> 0 | ES19: =+ES4*$C$19/$C$4 -> 0 | ET19: =+ET4*$C$19/$C$4 -> 0 | EU19: =+EU4*$C$19/$C$4 -> 0 | ... GB19: =+GB4*$C$19/$C$4 -> 0
A20: V | B20: ='1. Tổng hợp'!B23 -> Chi phí quản lý doanh nghiệp | C20: =C4*'1. Tổng hợp'!$D$23 -> 2.7926171e+10 | EN20: =+EN4*$C$20/$C$4 -> 0 | EO20: =+EO4*$C$20/$C$4 -> 0 | EP20: =+EP4*$C$20/$C$4 -> 0 | EQ20: =+EQ4*$C$20/$C$4 -> 0 | ER20: =+ER4*$C$20/$C$4 -> 0 | ES20: =+ES4*$C$20/$C$4 -> 0 | ET20: =+ET4*$C$20/$C$4 -> 0 | EU20: =+EU4*$C$20/$C$4 -> 0 | ... GB20: =+GB4*$C$20/$C$4 -> 0
A21: VI | B21: Chí phí tài chính: - Trong đó lãi vay | C21: ='4. Vay'!C23 -> 3.4643888e+10 | EN21: =+EN4*$C$21/$C$4 -> 0 | EO21: =+EO4*$C$21/$C$4 -> 0 | EP21: =+EP4*$C$21/$C$4 -> 0 | EQ21: =+EQ4*$C$21/$C$4 -> 0 | ER21: =+ER4*$C$21/$C$4 -> 0 | ES21: =+ES4*$C$21/$C$4 -> 0 | ET21: =+ET4*$C$21/$C$4 -> 0 | EU21: =+EU4*$C$21/$C$4 -> 0 | ... GB21: =+GB4*$C$21/$C$4 -> 0
A22: VII | B22: Lợi nhuận thuần từ hoạt động kinh doanh | C22: =SUM(EN22:GB22) -> 2.186062e+11 | EN22: =+EN14-EN19-EN20-EN21 -> 0 | EO22: =+EO14-EO19-EO20-EO21 -> 0 | EP22: =+EP14-EP19-EP20-EP21 -> 0 | EQ22: =+EQ14-EQ19-EQ20-EQ21 -> 0 | ER22: =+ER14-ER19-ER20-ER21 -> 0 | ES22: =+ES14-ES19-ES20-ES21 -> 0 | ET22: =+ET14-ET19-ET20-ET21 -> 0 | EU22: =+EU14-EU19-EU20-EU21 -> 0 | ... GB22: =+GB14-GB19-GB20-GB21 -> 0
A23: VIII | B23: Chi phí thuế thu nhập doanh nghiệp | C23: =SUM(EN23:GB23) -> 4.372124e+10 | EN23: =+EN22*'1. Tổng hợp'!$D$25 -> 0 | EO23: =+EO22*'1. Tổng hợp'!$D$25 -> 0 | EP23: =+EP22*'1. Tổng hợp'!$D$25 -> 0 | EQ23: =+EQ22*'1. Tổng hợp'!$D$25 -> 0 | ER23: =+ER22*'1. Tổng hợp'!$D$25 -> 0 | ES23: =+ES22*'1. Tổng hợp'!$D$25 -> 0 | ET23: =+ET22*'1. Tổng hợp'!$D$25 -> 0 | EU23: =+EU22*'1. Tổng hợp'!$D$25 -> 0 | ... GB23: =+GB22*'1. Tổng hợp'!$D$25 -> 0
A24: IX | B24: Lợi nhuận sau thuế thu nhập doanh nghiệp | C24: =SUM(EN24:GB24) -> 1.7488496e+11 | EN24: =+EN22-EN23 -> 0 | EO24: =+EO22-EO23 -> 0 | EP24: =+EP22-EP23 -> 0 | EQ24: =+EQ22-EQ23 -> 0 | ER24: =+ER22-ER23 -> 0 | ES24: =+ES22-ES23 -> 0 | ET24: =+ET22-ET23 -> 0 | EU24: =+EU22-EU23 -> 0 | ... GB24: =+GB22-GB23 -> 0
B26: ROS | C26: =C24/C4 -> 0.12524808
B27: Hiệu quả dự án | ER27: 2024 | ES27: 2025 | ET27: 2026 | EU27: 2027 | EV27: 2028 | EW27: 2029
A28: NPV | C28: ='8. Hiệu quả dự án và CĐT'!C20 -> 7.6848969e+10 | ER28: =ER4 -> 0 | ES28: =SUM(ES4:EV4) -> 0 | ET28: =SUM(EW4:EZ4) -> 0 | EU28: =SUM(FA4:FD4) -> 0 | EV28: =SUM(FE4:FH4) -> 0
A29: IRR | C29: ='8. Hiệu quả dự án và CĐT'!C21 -> 0.11584594
A30: Thời gian hoàn vốn | C30: ='8. Hiệu quả dự án và CĐT'!C22 -> 3 | D30: ='8. Hiệu quả dự án và CĐT'!D22 -> 3.5220057
B31: Hiệu quả CĐT
A32: NPV | C32: ='8. Hiệu quả dự án và CĐT'!C48 -> 1.6125998e+10
A33: IRR | C33: ='8. Hiệu quả dự án và CĐT'!C49 -> 0.17607408
A34: Thời gian hoàn vốn | C34: ='8. Hiệu quả dự án và CĐT'!C50 -> 3 | D34: ='8. Hiệu quả dự án và CĐT'!D50 -> 0.92859742

Sheet 8. Hiệu quả dự án và CĐT
A1: BẢNG 8: HIỆU QUẢ ĐẦU TƯ DỰ ÁN
D4: =YEAR(D5) -> 2023 | E4: =YEAR(E5) -> 2024 | F4: =YEAR(F5) -> 2024 | G4: =YEAR(G5) -> 2024 | H4: =YEAR(H5) -> 2024 | I4: =YEAR(I5) -> 2025 | J4: =YEAR(J5) -> 2025 | K4: =YEAR(K5) -> 2025 | ... AR4: =YEAR(AR5) -> 2033
A5: STT | B5: Dòng tiền dự án | C5: TỔNG | D5: =+'4. Vay'!E6 -> 45291 | E5: =+'4. Vay'!F6 -> 45382 | F5: =+'4. Vay'!G6 -> 45473 | G5: =+'4. Vay'!H6 -> 45565 | H5: =+'4. Vay'!I6 -> 45657 | I5: =+'4. Vay'!J6 -> 45747 | J5: =+'4. Vay'!K6 -> 45838 | K5: =+'4. Vay'!L6 -> 45930 | ... AR5: =+'4. Vay'!AS6 -> 48944
A6: I | B6: Dòng tiền thu từ dự án (cả VAT) | C6: =SUM(D6:AR6) -> 1535939420000 | D6: =+'5. KHBH'!FK12 -> 0 | E6: =+'5. KHBH'!FL12 -> 0 | F6: =+'5. KHBH'!FM12 -> 0 | G6: =+'5. KHBH'!FN12 -> 0 | H6: =+'5. KHBH'!FO12 -> 0 | I6: =+'5. KHBH'!FP12 -> 0 | J6: =+'5. KHBH'!FQ12 -> 0 | K6: =+'5. KHBH'!FR12 -> 0 | ... AR6: =+'5. KHBH'!GY12 -> 0
A7: II | B7: Dòng tiền chi cho dự án (ko lãi vay) | C7: =SUM(D7:AR7) -> 1.2813932e+12 | D7: =SUM(D8:D13) -> 0 | E7: =SUM(E8:E13) -> 0 | F7: =SUM(F8:F13) -> 0 | G7: =SUM(G8:G13) -> 0 | H7: =SUM(H8:H13) -> 0 | I7: =SUM(I8:I13) -> 0 | J7: =SUM(J8:J13) -> 0 | K7: =SUM(K8:K13) -> 0 | ... AR7: =SUM(AR8:AR13) -> 0
A8: 1 | B8: =+'3. TMDT'!B6 -> Tổng chi phí đầu tư xây dựng dự án | C8: =SUM(D8:AR8) -> 1.0990918e+12 | D8: =+'3. TMDT'!K6 -> 0 | E8: =+'3. TMDT'!L6 -> 0 | F8: =+'3. TMDT'!M6 -> 0 | G8: =+'3. TMDT'!N6 -> 0 | H8: =+'3. TMDT'!O6 -> 0 | I8: =+'3. TMDT'!P6 -> 0 | J8: =+'3. TMDT'!Q6 -> 0 | K8: =+'3. TMDT'!R6 -> 0 | ... AR8: =+'3. TMDT'!AY6 -> 0
A9: 2 | B9: =+'3. TMDT'!B10 -> Chi phí GPMB và tiền sử dụng đất | C9: =SUM(D9:AR9) -> 43014372094 | D9: =+'3. TMDT'!K10 -> 0 | E9: =+'3. TMDT'!L10 -> 0 | F9: =+'3. TMDT'!M10 -> 0 | G9: =+'3. TMDT'!N10 -> 0 | H9: =+'3. TMDT'!O10 -> 0 | I9: =+'3. TMDT'!P10 -> 0 | J9: =+'3. TMDT'!Q10 -> 0 | K9: =+'3. TMDT'!R10 -> 0 | ... AR9: =+'3. TMDT'!AY10 -> 0
A10: 3 | B10: Chi phí bán hàng | C10: =SUM(D10:AR10) -> 30718788400 | D10: =+'5. KHBH'!FK12*'1. Tổng hợp'!$D$19 -> 0 | E10: =+'5. KHBH'!FL12*'1. Tổng hợp'!$D$19 -> 0 | F10: =+'5. KHBH'!FM12*'1. Tổng hợp'!$D$19 -> 0 | G10: =+'5. KHBH'!FN12*'1. Tổng hợp'!$D$19 -> 0 | H10: =+'5. KHBH'!FO12*'1. Tổng hợp'!$D$19 -> 0 | I10: =+'5. KHBH'!FP12*'1. Tổng hợp'!$D$19 -> 0 | J10: =+'5. KHBH'!FQ12*'1. Tổng hợp'!$D$19 -> 0 | K10: =+'5. KHBH'!FR12*'1. Tổng hợp'!$D$19 -> 0 | ... AR10: =+'5. KHBH'!GY12*'1. Tổng hợp'!$D$19 -> 0
A11: 4 | B11: ='1. Tổng hợp'!B23 -> Chi phí quản lý doanh nghiệp | C11: =SUM(D11:AR11) -> 30718788400 | D11: =+D6*'1. Tổng hợp'!$D$23 -> 0 | E11: =+E6*'1. Tổng hợp'!$D$23 -> 0 | F11: =+F6*'1. Tổng hợp'!$D$23 -> 0 | G11: =+G6*'1. Tổng hợp'!$D$23 -> 0 | H11: =+H6*'1. Tổng hợp'!$D$23 -> 0 | I11: =+I6*'1. Tổng hợp'!$D$23 -> 0 | J11: =+J6*'1. Tổng hợp'!$D$23 -> 0 | K11: =+K6*'1. Tổng hợp'!$D$23 -> 0 | ... AR11: =+AR6*'1. Tổng hợp'!$D$23 -> 0
A12: 5 | B12: Thuế thu nhập doanh nghiệp | C12: =SUM(D12:AR12) -> 4.372124e+10 | D12: =+'7. P&L TOÀN DỰ ÁN'!EN23 -> 0 | E12: =+'7. P&L TOÀN DỰ ÁN'!EO23 -> 0 | F12: =+'7. P&L TOÀN DỰ ÁN'!EP23 -> 0 | G12: =+'7. P&L TOÀN DỰ ÁN'!EQ23 -> 0 | H12: =+'7. P&L TOÀN DỰ ÁN'!ER23 -> 0 | I12: =+'7. P&L TOÀN DỰ ÁN'!ES23 -> 0 | J12: =+'7. P&L TOÀN DỰ ÁN'!ET23 -> 0 | K12: =+'7. P&L TOÀN DỰ ÁN'!EU23 -> 0 | ... AR12: =+'7. P&L TOÀN DỰ ÁN'!GB23 -> 0
A13: 6 | B13: Thuế VAT phải nộp nhà nước | C13: =SUM(D13:AR13) -> 3.4128183e+10 | D13: 0 | E13: 0 | F13: 0 | G13: 0 | H13: =SUM(D16:H16) -> 0 | I13: =I16 -> 0 | J13: 0 | K13: 0 | L13: 0 | M13: 0 | N13: 0 | O13: 0 | P13: 0 | Q13: 0 | R13: 0 | S13: 0 | T13: 0 | U13: 0 | V13: 0 | W13: 0 | X13: 0 | Y13: 0 | Z13: 0 | AA13: 0 | AB13: 0 | AC13: 0 | AD13: 0 | AE13: 0 | AF13: 0 | AG13: 0 | AH13: =SUM(D16:AH16) -> 3.4128183e+10 | AI13: =AI16 -> 0 | AJ13: =AJ16 -> 0 | AK13: =AK16 -> 0 | AL13: =AL16 -> 0 | AM13: =AM16 -> 0 | AN13: =AN16 -> 0 | AO13: =AO16 -> 0 | AP13: =AP16 -> 0 | ... AR13: =AR16 -> 0
B14: Thuế VAT đầu ra | C14: =SUM(D14:AR14) -> 1.3963086e+11 | D14: =+(D6/(1+'1. Tổng hợp'!$D$24))*'1. Tổng hợp'!$D$24 -> 0 | E14: =+(E6/(1+'1. Tổng hợp'!$D$24))*'1. Tổng hợp'!$D$24 -> 0 | F14: =+(F6/(1+'1. Tổng hợp'!$D$24))*'1. Tổng hợp'!$D$24 -> 0 | G14: =+(G6/(1+'1. Tổng hợp'!$D$24))*'1. Tổng hợp'!$D$24 -> 0 | H14: =+(H6/(1+'1. Tổng hợp'!$D$24))*'1. Tổng hợp'!$D$24 -> 0 | I14: =+(I6/(1+'1. Tổng hợp'!$D$24))*'1. Tổng hợp'!$D$24 -> 0 | J14: =+(J6/(1+'1. Tổng hợp'!$D$24))*'1. Tổng hợp'!$D$24 -> 0 | K14: =+(K6/(1+'1. Tổng hợp'!$D$24))*'1. Tổng hợp'!$D$24 -> 0 | ... AR14: =+(AR6/(1+'1. Tổng hợp'!$D$24))*'1. Tổng hợp'!$D$24 -> 0
B15: Thuế VAT đầu vào | C15: =SUM(D15:AR15) -> 1.0550267e+11 | D15: =+((D8+D10+D11)/(1+'1. Tổng hợp'!$D$24))*'1. Tổng hợp'!$D$24 -> 0 | E15: =+((E8+E10+E11)/(1+'1. Tổng hợp'!$D$24))*'1. Tổng hợp'!$D$24 -> 0 | F15: =+((F8+F10+F11)/(1+'1. Tổng hợp'!$D$24))*'1. Tổng hợp'!$D$24 -> 0 | G15: =+((G8+G10+G11)/(1+'1. Tổng hợp'!$D$24))*'1. Tổng hợp'!$D$24 -> 0 | H15: =+((H8+H10+H11)/(1+'1. Tổng hợp'!$D$24))*'1. Tổng hợp'!$D$24 -> 0 | I15: =+((I8+I10+I11)/(1+'1. Tổng hợp'!$D$24))*'1. Tổng hợp'!$D$24 -> 0 | J15: =+((J8+J10+J11)/(1+'1. Tổng hợp'!$D$24))*'1. Tổng hợp'!$D$24 -> 0 | K15: =+((K8+K10+K11)/(1+'1. Tổng hợp'!$D$24))*'1. Tổng hợp'!$D$24 -> 0 | ... AR15: =+((AR8+AR10+AR11)/(1+'1. Tổng hợp'!$D$24))*'1. Tổng hợp'!$D$24 -> 0
B16: VAT đầu ra - đầu vào | C16: =SUM(D16:AR16) -> 3.4128183e+10 | D16: =D14-D15 -> 0 | E16: =E14-E15 -> 0 | F16: =F14-F15 -> 0 | G16: =G14-G15 -> 0 | H16: =H14-H15 -> 0 | I16: =I14-I15 -> 0 | J16: =J14-J15 -> 0 | K16: =K14-K15 -> 0 | ... AR16: =AR14-AR15 -> 0
A17: III | B17: Dòng Tiền Thuần | C17: =SUM(D17:AR17) -> 2.5454622e+11 | D17: =D6-D7 -> 0 | E17: =E6-E7 -> 0 | F17: =F6-F7 -> 0 | G17: =G6-G7 -> 0 | H17: =H6-H7 -> 0 | I17: =I6-I7 -> 0 | J17: =J6-J7 -> 0 | K17: =K6-K7 -> 0 | ... AR17: =AR6-AR7 -> 0
A18: IV | B18: Luỹ kế dòng tiền thuần | C18: =AR18 -> 2.5454622e+11 | D18: =D17 -> 0 | E18: =D18+E17 -> 0 | F18: =E18+F17 -> 0 | G18: =F18+G17 -> 0 | H18: =G18+H17 -> 0 | I18: =H18+I17 -> 0 | J18: =I18+J17 -> 0 | K18: =J18+K17 -> 0 | L18: =K18+L17 -> 0 | ... AR18: =AQ18+AR17 -> 2.5454622e+11
A20: NPV | C20: =I21+NPV('1. Tổng hợp'!E33,J21:Q21) -> 7.6848969e+10 | F20: Year | G20: 2023 | H20: 2024 | I20: =H20+1 -> 2025 | J20: =I20+1 -> 2026 | K20: =J20+1 -> 2027 | L20: =K20+1 -> 2028 | M20: =L20+1 -> 2029 | N20: =M20+1 -> 2030 | O20: =N20+1 -> 2031 | P20: =O20+1 -> 2032 | Q20: =P20+1 -> 2033
A21: MIRR | C21: =IRR(I22:Q22) -> 0.11584594 | F21: Cash Flow | G21: =SUMIFS($D$17:$AR$17,$D$4:$AR$4,G20) -> 0 | H21: =SUMIFS($D$17:$AR$17,$D$4:$AR$4,H20) -> 0 | I21: =SUMIFS($D$17:$AR$17,$D$4:$AR$4,I20) -> 0 | J21: =SUMIFS($D$17:$AR$17,$D$4:$AR$4,J20) -> -5.9256029e+11 | K21: =SUMIFS($D$17:$AR$17,$D$4:$AR$4,K20) -> -2.2504428e+11 | L21: =SUMIFS($D$17:$AR$17,$D$4:$AR$4,L20) -> 456804984960 | M21: =SUMIFS($D$17:$AR$17,$D$4:$AR$4,M20) -> 4.5556059e+11 | N21: =SUMIFS($D$17:$AR$17,$D$4:$AR$4,N20) -> 1.0604446e+11 | ... Q21: =SUMIFS($D$17:$AR$17,$D$4:$AR$4,Q20) -> 0
A22: Thời gian hoàn vốn | C22: =COUNTIFS(I23:Q23,"<0") -> 3 | D22: {=12-ABS(INDEX($I$22:$Q$23,2,C22+1)/INDEX($I$22:$Q$23,1,C22+1))*12+1} -> 3.5220057 | F22: Quy đổi (triệu VNĐ) | G22: =G21/10^6 -> 0 | H22: =H21/10^6 -> 0 | I22: =I21/10^6 -> 0 | J22: =J21/10^6 -> -592560.29 | K22: =K21/10^6 -> -225044.28 | L22: =L21/10^6 -> 456804.98 | M22: =M21/10^6 -> 455560.59 | N22: =N21/10^6 -> 106044.46 | ... Q22: =Q21/10^6 -> 0
A23: XNPV | B23: XNPV | C23: =XNPV('1. Tổng hợp'!$E$33,L17:AR17,L5:AR5)+SUM(D17:K17) -> 9.6698192e+10 | F23: Lũy kế | G23: =SUM($G$22:G22) -> 0 | H23: =SUM($G$22:H22) -> 0 | I23: =SUM($G$22:I22) -> 0 | J23: =SUM($G$22:J22) -> -592560.29 | K23: =SUM($G$22:K22) -> -817604.57 | L23: =SUM($G$22:L22) -> -360799.59 | M23: =SUM($G$22:M22) -> 94761.006 | N23: =SUM($G$22:N22) -> 200805.47 | ... Q23: =SUM($G$22:Q22) -> 254546.22
A24: XIRR | B24: XIRR | C24: =XIRR(E17:AR17,E5:AR5) -> 2.9802322e-09
A26: CHECK | C26: =+C18-'4. Vay'!C22-'4. Vay'!C23 -> 1.7488496e+11
D27: =YEAR(D28) -> 2023 | E27: =YEAR(E28) -> 2024 | F27: =YEAR(F28) -> 2024 | G27: =YEAR(G28) -> 2024 | H27: =YEAR(H28) -> 2024 | I27: =YEAR(I28) -> 2025 | J27: =YEAR(J28) -> 2025 | K27: =YEAR(K28) -> 2025 | ... AR27: =YEAR(AR28) -> 2033
A28: STT | B28: Dòng tiền chủ đầu tư | C28: TỔNG | D28: =D5 -> 45291 | E28: =E5 -> 45382 | F28: =F5 -> 45473 | G28: =G5 -> 45565 | H28: =H5 -> 45657 | I28: =I5 -> 45747 | J28: =J5 -> 45838 | K28: =K5 -> 45930 | ... AR28: =AR5 -> 48944
A29: I | B29: Dòng vào | C29: =SUM(C30:C31) -> 2.3354138e+12 | D29: =D30+D31 -> 0 | E29: =E30+E31 -> 0 | F29: =F30+F31 -> 0 | G29: =G30+G31 -> 0 | H29: =H30+H31 -> 0 | I29: =I30+I31 -> 0 | J29: =J30+J31 -> 0 | K29: =K30+K31 -> 0 | ... AR29: =AR30+AR31 -> 0
A30: 1 | B30: Dòng tiền thu từ dự án (cả VAT) | C30: =SUM(D30:AR30) -> 1535939420000 | D30: =+'5. KHBH'!FK12 -> 0 | E30: =+'5. KHBH'!FL12 -> 0 | F30: =+'5. KHBH'!FM12 -> 0 | G30: =+'5. KHBH'!FN12 -> 0 | H30: =+'5. KHBH'!FO12 -> 0 | I30: =+'5. KHBH'!FP12 -> 0 | J30: =+'5. KHBH'!FQ12 -> 0 | K30: =+'5. KHBH'!FR12 -> 0 | ... AR30: =+'5. KHBH'!GY12 -> 0
A31: 2 | B31: Vốn vay | C31: =SUM(D31:AR31) -> 7.9947434e+11 | D31: =+'4. Vay'!E9 -> 0 | E31: =+'4. Vay'!F9 -> 0 | F31: =+'4. Vay'!G9 -> 0 | G31: =+'4. Vay'!H9 -> 0 | H31: =+'4. Vay'!I9 -> 0 | I31: =+'4. Vay'!J9 -> 0 | J31: =+'4. Vay'!K9 -> 0 | K31: =+'4. Vay'!L9 -> 0 | ... AR31: =+'4. Vay'!AS9 -> 0
A32: II | B32: Dòng tiền chi cho dự án (ko lãi vay) | C32: =SUM(D32:AR32) -> 2.1605288e+12 | D32: =SUM(D33:D41) -> 0 | E32: =SUM(E33:E41) -> 0 | F32: =SUM(F33:F41) -> 0 | G32: =SUM(G33:G41) -> 0 | H32: =SUM(H33:H41) -> 0 | I32: =SUM(I33:I41) -> 0 | J32: =SUM(J33:J41) -> 0 | K32: =SUM(K33:K41) -> 0 | ... AR32: =SUM(AR33:AR41) -> 0
A33: 1 | B33: Tổng chi phí đầu tư xây dựng dự án không bao gồm lãi vay | C33: =SUM(D33:AR33) -> 1.0990918e+12 | D33: =+'3. TMDT'!K6 -> 0 | E33: =+'3. TMDT'!L6 -> 0 | F33: =+'3. TMDT'!M6 -> 0 | G33: =+'3. TMDT'!N6 -> 0 | H33: =+'3. TMDT'!O6 -> 0 | I33: =+'3. TMDT'!P6 -> 0 | J33: =+'3. TMDT'!Q6 -> 0 | K33: =+'3. TMDT'!R6 -> 0 | ... AR33: =+'3. TMDT'!AY6 -> 0
A34: 2 | B34: Lãi vay trong giai đoạn xây dựng | C34: =SUM(D34:AR34) -> 4.501737e+10 | D34: =+'4. Vay'!E22 -> 0 | E34: =+'4. Vay'!F22 -> 0 | F34: =+'4. Vay'!G22 -> 0 | G34: =+'4. Vay'!H22 -> 0 | H34: =+'4. Vay'!I22 -> 0 | I34: =+'4. Vay'!J22 -> 0 | J34: =+'4. Vay'!K22 -> 0 | K34: =+'4. Vay'!L22 -> 0 | ... AR34: =+'4. Vay'!AS22 -> 0
A35: 3 | B35: Lãi vay trong kỳ | C35: =SUM(D35:AR35) -> 3.4643888e+10 | D35: =+'4. Vay'!E23 -> 0 | E35: =+'4. Vay'!F23 -> 0 | F35: =+'4. Vay'!G23 -> 0 | G35: =+'4. Vay'!H23 -> 0 | H35: =+'4. Vay'!I23 -> 0 | I35: =+'4. Vay'!J23 -> 0 | J35: =+'4. Vay'!K23 -> 0 | K35: =+'4. Vay'!L23 -> 0 | ... AR35: =+'4. Vay'!AS23 -> 0
